Workbook

Sheet Epics
A1: Epic ID | B1: Epic Name | C1: Story Count | D1: Cadence Spread | E1: FR Coverage
A2: EP-01 | B2: Inquiry and Client Onboarding | C2: 4 | D2: C1 | E2: FR-01, FR-46, FR-48, FR-51, FR-52; FL-001
A3: EP-02 | B3: PMCM Command and Coordination | C3: 5 | D3: C1, C2 | E3: FL-003, FL-008, FL-017; FR-88, FR-89, FR-90, FR-91
A4: EP-03 | B4: Briefing and Proposal | C4: 2 | D4: C2 | E4: FR-19, FR-58, FR-59, FR-60, FR-61, FR-62; FL-005, FL-006
A5: EP-04 | B5: Contract and Conforme | C5: 2 | D5: C2, C3 | E5: FR-03, FR-67, FR-68, FR-69, FR-70, FR-96, FR-97, New-SY4; FL-002
A6: EP-05 | B6: Floor Plan and Venue | C6: 4 | D6: C2 | E6: FR-08, FR-28, FR-29, FR-66, FR-80, FR-81, FR-82, FR-83, FR-84; FL-011, FL-016, FL-018
A7: EP-06 | B7: Compliance and Change Enablement | C7: 3 | D7: C3 | E7: FR-06, FR-07, New-SY3, New-SY4; FL-009
A8: EP-07 | B8: Supplier Network and Readiness | C8: 10 | D8: C1, C2, C3, C4 | E8: FR-14 to FR-18, FR-35 to FR-38, FR-49, FR-63, FR-64, FR-75 to FR-79, FR-87, FR-AI-06, New-S1 to New-S5, New-SUP1 to New-SUP4; FL-007, FL-022
A9: EP-08 | B9: Finance and Billing | C9: 3 | D9: C2, C3 | E9: FR-20, FR-21, FR-69, FR-92, FR-93, FR-94, New-P5; FL-010
A10: EP-09 | B10: File and Document Management | C10: 2 | D10: C2, C3 | E10: FR-04, FR-32, FR-33, FR-38, New-SEC3; FL-006, FL-024
A11: EP-10 | B11: Client Portal | C11: 3 | D11: C2, C3 | E11: FR-26 to FR-34, FR-65, FR-66, New-CL1, New-CL2; FL-004, FL-020
A12: EP-11 | B12: Coordinator Experience and Live Ops | C12: 5 | D12: C2, C3 | E12: FR-88 to FR-91, New-C1 to New-C4, New-CO1 to New-CO6; FL-008
A13: EP-12 | B13: Event Day Operations | C13: 6 | D13: C3, C4 | E13: FR-05, FR-40, FR-78, FR-AI-04, FR-AI-07, New-SY1, New-SY2; FL-019
... A19: EP-18 | B19: Design System and Shared UI | C19: 2 | D19: C1, C2 | E19: FL-016; packages/ui, design tokens, shared shell patterns

Sheet Tracker
A1: Epic ID | B1: Epic | C1: Story ID | D1: User Story | E1: Acceptance Criteria | F1: Priority (MoSCoW) | G1: Owner / Role | H1: Status | I1: Dependencies | J1: Notes | K1: Completion %
A2: EP-01 -- Inquiry and Client Onboarding
A3: EP-01 | B3: Inquiry and Client Onboarding | C3: EP-01-S01 | D3: As a prospective Client, I want to submit an event inquiry, so that PMCM can assess my event needs. | E3: 1. PASS: Public inquiry form is accessible without login or account creation. 2. PASS: Form captures all required fields: full name, contact number, email address, company or organization name, event type, preferred event date, expected headcount, and client type (individual or corporate). 3. PASS: Referral source dropdown is present with five confirmed values: Facebook, Website, BNI, Walk-In, Log on Behalf. Sixth value pending PA-62 resolution with Ms. Mys. 4. PASS: On submission, system checks for duplicate inquiry from same email or contact number; if duplicate detected, clear message shown and duplicate record not created. 5. PASS: If submitting email or contact number matches a previously rejected inquiry, previous rejection flag is surfaced to PMCM Admin on inquiry detail view (not shown to prospective client). 6. PASS: Submitted inquiry appears in PMCM Admin inquiry inbox with all submitted field values intact and readable. 7. PASS: Inquiry record stores client type field value (individual or corporate) and value is visible to PMCM Admin on detail view. 8. PASS: Submitter receives a confirmation acknowledgment (on-screen or email) after successful submission. 9. FAIL trigger: Form is inaccessible without login, any required field is absent, duplicate detection fails, previous rejection flag not surfaced to PMCM Admin, client type field missing, or confirmation acknowledgment absent. | F3: Must | G3: C (Ethan) | H3: Done | I3: None | J3: FR-01, FR-46, FR-51. PA-62 OPEN -- sixth referral source value pending Ms. Mys confirmation. Five confirmed values from codebase: Facebook, Website, BNI, Walk-In, Log on Behalf. | K3: =IF(H3="Done",1,IF(H3="In Progress",0.5,IF(H3="In Review",0.75,0))) -> 1
A4: EP-01 | B4: Inquiry and Client Onboarding | C4: EP-01-S02 | D4: As a PMCM Admin, I want to log an inquiry on behalf of a walk-in or phone client, so that all inquiries enter the same system regardless of channel. | E4: 1. PASS: PMCM Admin can access a Log Inquiry on Behalf function from within the PMCM command surface without navigating to the public inquiry form. 2. PASS: On-behalf form captures same required fields as public inquiry form: full name, contact number, email address, company or organization name, event type, preferred event date, expected headcount, client type, and referral source. 3. PASS: Resulting inquiry record is marked as logged on behalf of a client (channel: walk-in or phone), distinguishable from self-submitted inquiries in PMCM Admin inbox. 4. PASS: Non-PMCM actors (client, supplier, coordinator, guest) cannot access or trigger the logInquiryOnBehalf function. Any attempt returns an authorization denial with no data exposed. 5. PASS: Duplicate detection and previous rejection flag logic applies identically to on-behalf submissions as to public submissions. 6. PASS: Logged inquiry appears in PMCM Admin inquiry inbox with all field values intact, channel marker visible, and logging admin identity recorded. 7. FAIL trigger: On-behalf function is accessible to non-PMCM actors, channel marker is absent, duplicate detection is bypassed, or logging admin identity is not recorded. | F4: Must | G4: B (Francis) | H4: Done | I4: None | J4: FR-52; logInquiryOnBehalf; non-PMCM actors blocked; confirmed Live per File 9. | K4: =IF(H4="Done",1,IF(H4="In Progress",0.5,IF(H4="In Review",0.75,0))) -> 1
A5: EP-01 | B5: Inquiry and Client Onboarding | C5: EP-01-S03 | D5: As a PMCM Admin, I want to onboard a new client account after inquiry approval, so that the client can access their portal. | E5: 1. PASS: PMCM Admin can trigger client onboarding only after an inquiry has been approved; onboarding action unavailable on inquiries in any other status (Pending, Declined, Duplicate). 2. PASS: Onboarding creates a client account with login credentials and associates it with the approved inquiry record. 3. PASS: Newly created client account activates access to client portal (apps/client, port 3001) for that client and no other portal. 4. PASS: Client receives login credentials or an account activation link after onboarding is triggered by PMCM Admin. 5. PASS: Non-PMCM actors cannot trigger client onboarding. Any attempt returns an authorization denial with no data exposed. 6. PASS: Onboarding event produces an audit log entry recording the onboarding admin identity, timestamp, and associated inquiry ID. 7. FAIL trigger: Onboarding is triggerable before inquiry approval, client account is not associated with the inquiry record, client receives access to portals other than apps/client, or audit log entry is absent. | F5: Must | G5: D (Anthony) | H5: Done | I5: None | J5: FR-46; ClientOnboardingWorkflowService inside inquiry-onboarding module; confirmed Live per File 9. | K5: =IF(H5="Done",1,IF(H5="In Progress",0.5,IF(H5="In Review",0.75,0))) -> 1
A6: EP-01 | B6: Inquiry and Client Onboarding | C6: EP-01-S04 | D6: As a PMCM Admin, I want the referral source dropdown to capture exactly six confirmed values, so that inquiry source data is consistent and reportable. | E6: 1. PASS: Referral source dropdown is present on both the public inquiry form and the Log Inquiry on Behalf form. 2. PASS: Dropdown contains exactly six options. [PLACEHOLDER: five confirmed from codebase -- Facebook, Website, BNI, Walk-In, Log on Behalf. Sixth value pending PA-62 resolution with Ms. Mys.] 3. PASS: Referral source field is required; form cannot be submitted without a selection. 4. PASS: Selected referral source value is saved to the inquiry record and visible to PMCM Admin on inquiry detail view. 5. PASS: Referral source field value is preserved through duplicate detection and on-behalf submission flows without being lost or overwritten. 6. FAIL trigger: Dropdown is absent from either form, fewer or more than six options are present, field is optional and submittable without a selection, or saved value does not appear on PMCM Admin inquiry detail view. | F6: Must | G6: B (Francis) | H6: Done | I6: None | J6: FR-48; PA-62 OPEN -- Francis confirmed five values from codebase. Sixth value must be confirmed with Ms. Mys before AC item 2 is finalized. | K6: =IF(H6="Done",1,IF(H6="In Progress",0.5,IF(H6="In Review",0.75,0))) -> 1
A7: EP-02 -- PMCM Command and Coordination
A8: EP-02 | B8: PMCM Command and Coordination | C8: EP-02-S01 | D8: As a PMCM Admin, I want a command inbox showing critical alerts and pending actions, so that I can manage all active events from one surface. | E8: 1. PASS: Command inbox is accessible from the PMCM Admin dashboard in apps/event (port 3004) without additional navigation steps. 2. PASS: Inbox displays rows sourced from the PrismPmcmCommandInbox contract; each row contains at minimum: event name, alert type, severity level, and timestamp. 3. PASS: Critical severity alerts are visually distinguished from lower severity alerts (rose/red AlertTriangle icon confirmed per FL-017 build). 4. PASS: Inbox reflects current state of all active events; stale or resolved alerts do not persist after resolution. 5. PASS: Non-PMCM actors (client, supplier, coordinator, guest) cannot access the command inbox. Any attempt returns an authorization denial with no data exposed. 6. PASS: Inbox renders correctly in an empty state (no active alerts) with a clear empty state message; does not show a false all-clear when data fetch has not yet resolved. 7. PASS: Command inbox component is wired into EventDashboardClient.tsx at sections B, J, K, L as implemented; barrel export is present and resolves without error. 8. FAIL trigger: Inbox is inaccessible from PMCM dashboard, rows do not source from PrismPmcmCommandInbox contract, critical severity alerts are not visually distinguished, non-PMCM actors can access inbox data, or component throws an error on mount. | F8: Must | G8: B (Francis) | H8: Done | I8: None | J8: FL-017; PrismPmcmCommandInbox contract exists and feeds dashboard rows; confirmed Live per File 9. AC item 6 covers empty state only; error state is EP-02-S02 scope. | K8: =IF(H8="Done",1,IF(H8="In Progress",0.5,IF(H8="In Review",0.75,0))) -> 1
A9: EP-02 | B9: PMCM Command and Coordination | C9: EP-02-S02 | D9: As a PMCM Admin, I want the command inbox error state to correctly reflect system failures rather than showing a false all-clear, so that I am never misled about system health. | E9: 1. PASS: When command inbox data fetch fails (network error, API error, or timeout), inbox displays a visible error state with a clear message indicating a system failure; it does not display an empty inbox or an all-clear message. 2. PASS: Error state is visually distinct from both the empty state (no alerts) and the loaded state (alerts present); a user cannot mistake a fetch failure for a genuine all-clear. 3. PASS: Error state does not expose raw error details, stack traces, or internal system information to the PMCM Admin. 4. PASS: When underlying data fetch recovers, inbox transitions from error state to the correct loaded or empty state without requiring a full page reload. 5. PASS: The false all-clear chain identified in FL-017 post-build deferred item 1 is fully resolved; no code path exists where a fetch failure renders the inbox as empty-and-healthy. 6. FAIL trigger: A fetch failure renders the inbox as empty or all-clear, error state is visually indistinguishable from empty state, raw error details are exposed to the user, or recovery from error state requires a full page reload. | F9: Must | G9: B (Francis) | H9: Done | I9: EP-02-S01 | J9: FL-017 deferred item 1 RESOLVED. Commit e0f99c0. Amber AlertTriangle error panel and '!' badge implemented. SILENT-001 and SILENT-008 cleared. Verified in Docker. | K9: =IF(H9="Done",1,IF(H9="In Progress",0.5,IF(H9="In Review",0.75,0))) -> 1
A10: EP-02 | B10: PMCM Command and Coordination | C10: EP-02-S03 | D10: As a PMCM Admin, I want to click through command inbox items to the relevant event workspace, so that I can act on alerts without manual navigation. | E10: 1. PASS: Each command inbox item is clickable and navigates the PMCM Admin directly to the relevant event workspace without additional navigation steps. 2. PASS: Destination route is correct for each alert type; a supplier alert routes to the supplier section, a billing alert routes to the billing section, and so on. 3. PASS: Click-through navigation preserves the inbox state; returning to the inbox after navigating away does not reset or reload the inbox unexpectedly. 4. PASS: Clicking a resolved or stale inbox item either routes correctly or shows a clear message that the item is no longer active; it does not route to a broken or empty workspace state. 5. PASS: Non-PMCM actors cannot trigger or access any click-through navigation route from the command inbox. 6. FAIL trigger: Any inbox item is non-clickable, click routes to an incorrect workspace section, click-through exposes non-PMCM workspace data to unauthorized actors, or a stale item click results in a broken route with no user feedback. | F10: Should | G10: B (Francis) | H10: Done | I10: EP-02-S01 | J10: FL-017 deferred item 2 RESOLVED. Commit a97498f. InboxItem conditionally wraps in Link using item.href. Verified in Docker. 404 on destination is expected and out of FL-017 scope. | K10: =IF(H10="Done",1,IF(H10="In Progress",0.5,IF(H10="In Review",0.75,0))) -> 1
A11: EP-02 | B11: PMCM Command and Coordination | C11: EP-02-S04 | D11: As a PMCM Admin, I want the command inbox mounted in its final approved location, so that the layout matches the accepted T03 design. | E11: 1. PASS: Command inbox is mounted at the location specified in the T03 acceptance notes, not in a standalone stub location. 2. PASS: Mounting location is confirmed by at least one other owner as matching the T03 design before this story moves to Done. 3. PASS: Mounted location does not introduce layout regressions on any other section of the PMCM Admin dashboard. 4. PASS: Command inbox retains all behavior from EP-02-S01, EP-02-S02, and EP-02-S03 after relocation; no AC items from those stories regress as a result of the mount change. 5. FAIL trigger: Inbox remains in standalone stub location after branches merge, mounting introduces layout regressions, or any prior AC item from EP-02-S01 through EP-02-S03 regresses after relocation. | F11: Could | G11: B (Francis) | H11: Done | I11: EP-02-S01, EP-02-S02, EP-02-S03 | J11: FL-017 deferred item 3 RESOLVED as non-issue. Mounting location requirement came from t03-acceptance-notes.md -- a Claude Code-generated memory file never approved by team, adviser, or client. Not in ClickUp. Not in whole-system calendar. Standalone route is correct per team plan. No code change needed. t03-acceptance-notes.md must be deleted from Claude Code memory. | K11: =IF(H11="Done",1,IF(H11="In Progress",0.5,IF(H11="In Review",0.75,0))) -> 1
A12: EP-02 | B12: PMCM Command and Coordination | C12: EP-02-S05 | D12: As a PMCM Admin, I want to view the full coordinator directory and issue assignment commands from the command surface, so that I can assign the right coordinators to each event without leaving the PMCM app. | E12: 1. PASS: PMCM Admin can view the full coordinator directory from within apps/event (port 3004) without navigating away from the command surface. 2. PASS: Directory displays each coordinator name, assigned role tags, skills tags, and current availability status. 3. PASS: PMCM Admin can issue an assignment command selecting a coordinator for a specific event and role; assignment is recorded in staffing-ops module. 4. PASS: System detects double-booking: if a coordinator is already assigned to another event on the same date, a clear warning is shown before the assignment is confirmed (FR-88). Assignment is not blocked automatically but warning must be visible and dismissible only with explicit PMCM Admin confirmation. 5. PASS: PMCM Admin can initiate a coordinator withdrawal or replacement from the same surface (FR-89); the replacement command updates the assignment record and logs the change. 6. PASS: After assignment is issued, coordinator assignment status appears as Pending Acknowledgment on the PMCM dashboard until the coordinator confirms (EP-11-S01 response side); PMCM Admin can see which assignments are unacknowledged. 7. PASS: FR-90 PMCM tracking side: PMCM Admin can track acknowledgment status per coordinator per event from this surface. 8. PASS: Coordinator directory and assignment data are accessible to PMCM Admin only; coordinator, client, supplier, and guest actors cannot access directory payloads or assignment command routes. 9. PASS: same_tx pattern is used for coordinator assignment commands per access-control module specification; assignment and audit log entry are atomic. 10. FAIL trigger: Double-booking warning is absent or suppressible without explicit confirmation, assignment data is accessible to non-PMCM actors, Pending Acknowledgment status is not shown after assignment is issued, or assignment and audit entry are not written atomically. | F12: Must | G12: B (Francis) | H12: In Progress | I12: None | J12: Absorbs EP-11-S04 (deleted from original scope). FL-008; staffing-ops module. FR-90 PMCM tracking side here; EP-11-S01 covers coordinator acknowledgment response side. ACTION: Francis to start after EP-04-S01. | K12: =IF(H12="Done",1,IF(H12="In Progress",0.5,IF(H12="In Review",0.75,0))) -> 0.5
A13: EP-03 -- Briefing and Proposal
A14: EP-03 | B14: Briefing and Proposal | C14: EP-03-S01 | D14: As a PMCM Admin, I want to create and send an event briefing to the client, so that expectations are aligned before proposal generation. | E14: 1. PASS: PMCM Admin can create an event briefing from within apps/event after conforme is signed (EP-04-S01 gate); briefing creation unavailable before conforme. 2. PASS: Briefing form captures at minimum: event objectives, scope of services, timeline and key milestones, PMCM responsibilities, and client responsibilities. 3. PASS: PMCM Admin can send the briefing to the client; client receives access to the briefing inside the client portal (apps/client). 4. PASS: Client can complete their portion of the briefing form inside the client portal; PMCM Admin is notified when client submission is received. 5. PASS: Briefing record is stored and retrievable per event; visible to PMCM Admin and the assigned client only. 6. PASS: Briefing status is trackable (Sent, Client Responded, Complete); status is visible on the PMCM command surface. 7. PASS: EP-03-S02 (proposal generation) is gated on briefing completion; the proposal action is unavailable until briefing status is Complete. 8. PASS: Supplier, coordinator, and guest actors cannot access briefing records or briefing form data. 9. FAIL trigger: Briefing is createable before conforme is signed, client cannot access the briefing in their portal, proposal action is available before briefing is complete, or briefing data is accessible to non-PMCM non-client actors. | F14: Must | G14: B (Francis) | H14: To Do | I14: EP-04-S01 | J14: FR-58; PA-81 phase ownership provisionally confirmed C2. EventBriefingPanel confirmed present in apps/event. GATE: EP-04-S01 must be Done first. | K14: =IF(H14="Done",1,IF(H14="In Progress",0.5,IF(H14="In Review",0.75,0))) -> 0
A15: EP-03 | B15: Briefing and Proposal | C15: EP-03-S02 | D15: As a PMCM Admin, I want to generate and send a proposal to the client, so that the client can review and respond before conforme. | E15: 1. PASS: PMCM Admin can generate a proposal from within apps/event after the event briefing is complete (EP-03-S01 gate); proposal action unavailable before briefing is Complete. 2. PASS: Proposal is handled by CommercialWorkflowService inside commercial-ops. 3. PASS: Proposal contains at minimum: Executive Summary, Event Concept, Service Package Summary, Investment Summary, and Payment Schedule. 4. PASS: PMCM Admin reviews and finalizes the proposal before sending; proposal cannot be sent in draft state without explicit PMCM Admin send action. 5. PASS: Client receives the proposal inside the client portal and can view all five sections. 6. PASS: Client can respond to the proposal (accept or request revision); PMCM Admin is notified of the client response. 7. PASS: Proposal revision history is stored; PMCM Admin can view prior proposal versions per event. 8. PASS: Proposal data (investment summary, payment schedule) is not visible to supplier, coordinator, or guest actors. 9. PASS: Conforme upload (EP-04-S01) is available only after the client has accepted the proposal; conforme action is gated on proposal acceptance. 10. FAIL trigger: Proposal is sendable before briefing is complete, proposal is sent without explicit PMCM Admin send action, financial data is accessible to non-PMCM non-client actors, or conforme action is available before proposal is accepted. | F15: Must | G15: B (Francis) | H15: To Do | I15: EP-03-S01 | J15: FR-60; commercial-ops; CommercialWorkflowService. AI proposal drafting (FR-AI-03) is Phase 2 scope and a separate story (EP-16-S02); this story covers manual proposal workflow only. | K15: =IF(H15="Done",1,IF(H15="In Progress",0.5,IF(H15="In Review",0.75,0))) -> 0
A16: EP-04 -- Contract and Conforme
A17: EP-04 | B17: Contract and Conforme | C17: EP-04-S01 | D17: As a PMCM Admin, I want to upload a signed conforme document, so that the client portal, billing workspace, and event workspace are atomically activated. | E17: 1. PASS: PMCM Admin can upload a signed conforme document from within apps/event; upload is handled via the inquiry-onboarding module uploadConforme path. 2. PASS: Conforme upload accepts PDF format only; non-PDF uploads are rejected with a clear error message. 3. PASS: On successful conforme upload, the following are activated atomically in a single transaction: client portal access for the assigned client, billing workspace for the event, and event workspace for PMCM Admin. 4. PASS: If any part of the atomic activation fails, none of the three activations complete; the system rolls back and PMCM Admin sees a clear failure message with no partial activation state. 5. PASS: Conforme document is stored and retrievable per event; PMCM Admin can view the uploaded conforme on the event record. 6. PASS: The 50% downpayment milestone is created as a billing record downstream (EP-08-S01 consequence); this story AC does not cover billing generation logic directly pending PA-109 resolution. 7. PASS: Client portal, billing workspace, and event workspace are inaccessible to their respective actors before conforme is uploaded; no partial access is granted on proposal acceptance alone. 8. PASS: Conforme document is not accessible to supplier, coordinator, or guest actors. 9. PASS: Conforme upload event produces an audit log entry recording the uploading admin identity, timestamp, and event ID. 10. FAIL trigger: Non-PDF file is accepted, atomic activation is partial, rollback does not occur on failure, conforme document is accessible to non-PMCM non-client actors, or audit log entry is absent on upload. | F17: Must | G17: B (Francis) | H17: In Progress | I17: None | J17: FR-03; conforme = master gate. PA-109 OPEN -- Anthony must confirm whether uploadConforme calls billing logic directly or routes through FinanceOpsModule. HIGHEST PRIORITY C2 DELIVERY -- gates 19 downstream stories. ACTION: Francis to start immediately. ACTION: Raise PA-109 with Anthony. | K17: =IF(H17="Done",1,IF(H17="In Progress",0.5,IF(H17="In Review",0.75,0))) -> 0.5
A18: EP-04 | B18: Contract and Conforme | C18: EP-04-S02 | D18: As a PMCM Admin, I want to generate and manage a contract or MOA for large clients, so that the legal agreement is documented and notarized where required. | E18: 1. PASS: PMCM Admin can generate a contract or MOA from within apps/event after conforme is signed (EP-04-S01 gate). 2. PASS: Contract or MOA captures at minimum: party names, event scope, payment terms, cancellation and postponement clauses, and notarization requirement flag. 3. PASS: Dual signing path is supported: e-signature is the primary path; physical signature fallback is available and documented per event. 4. PASS: PMCM Admin can track contract status (Draft, Sent, Signed, Notarized) per event. 5. PASS: Signed contract or MOA is stored and retrievable per event; PMCM Admin can view and download it. 6. PASS: Contract or MOA is not accessible to supplier, coordinator, or guest actors. 7. FAIL trigger: Contract is generatable before conforme is signed, dual signing path is not supported, signed document is not stored per event, or non-PMCM non-client actors can access contract data. | F18: Should | G18: B (Francis) | H18: To Do | I18: EP-04-S01 | J18: FR-67, FR-68; MOA for large clients; notarization requirement noted; dual signing path (e-signature primary, physical fallback). | K18: =IF(H18="Done",1,IF(H18="In Progress",0.5,IF(H18="In Review",0.75,0))) -> 0
A19: EP-05 -- Floor Plan and Venue
A20: EP-05 | B20: Floor Plan and Venue | C20: EP-05-S01 | D20: As a PMCM Admin, I want to build and publish an official floor plan for an event, so that the approved layout is available to all relevant parties. | E20: 1. PASS: PMCM Admin can create an official floor plan from within apps/event after conforme is signed (EP-04-S01 gate); floor plan creation is unavailable before conforme. 2. PASS: Floor plan creation is handled by FloorPlanWorkflowService inside the floorplan module. 3. PASS: PMCM Admin can publish the official floor plan; published snapshot is stored and retrievable per event. 4. PASS: Only PMCM Admin and system actors can mutate the official floor plan state; client, supplier, coordinator, and guest actors cannot mutate official floor plan state. 5. PASS: Client, supplier, and coordinator actors can fetch the published approved snapshot per their role permissions; no actor can access a snapshot beyond their confirmed role boundary. 6. PASS: Ocular visit task (EP-10-S03) must be marked complete by PMCM Admin before floor plan creation is available, unless PMCM Admin override path is confirmed (PA-59 resolution required). 7. PASS: FLOORPLAN_COMMANDS port is used for all write operations; no direct Prisma calls bypass the port abstraction. 8. FAIL trigger: Floor plan is createable before conforme is signed, non-PMCM actors can mutate official floor plan state, FLOORPLAN_COMMANDS port is bypassed, or ocular visit gate is absent without confirmed override path. | F20: Must | G20: B (Francis) | H20: To Do | I20: EP-04-S01 | J20: FL-016; FR-80; floorplan module confirmed extracted; FloorPlanWorkflowService; PMCM/system actors mutate official floorplans only; canvas/editor persistence unchanged. PA-59 OPEN on ocular visit override path. | K20: =IF(H20="Done",1,IF(H20="In Progress",0.5,IF(H20="In Review",0.75,0))) -> 0
A21: EP-05 | B21: Floor Plan and Venue | C21: EP-05-S02 | D21: As a Client, I want to submit my venue and layout preferences, so that PMCM can incorporate them into the official floor plan. | E21: 1. PASS: Client can submit venue and layout preferences from within the client portal (apps/client) after conforme is signed (EP-04-S01 gate). 2. PASS: Preference submission is clearly labeled as a preference draft, not an official floor plan; client cannot mistake their preference submission for the official layout. 3. PASS: Client preferences are stored and retrievable by PMCM Admin per event; PMCM Admin decides whether to incorporate preferences into the official floor plan. 4. PASS: Client can submit preferences only once; revision requires PMCM Admin to reopen the preference window. 5. PASS: Client cannot view or access the official floor plan state until PMCM Admin publishes it. 6. PASS: Supplier, coordinator, and guest actors cannot access client preference submissions. 7. FAIL trigger: Client preference submission is labeled as an official floor plan, client can mutate official floor plan state, or non-client non-PMCM actors can access preference data. | F21: Must | G21: C (Ethan) | H21: To Do | I21: EP-04-S01, EP-05-S01 | J21: FL-018; FR-28; client submits preferences only -- cannot mutate official state. Labeled as preference draft not a floor plan. | K21: =IF(H21="Done",1,IF(H21="In Progress",0.5,IF(H21="In Review",0.75,0))) -> 0
A22: EP-05 | B22: Floor Plan and Venue | C22: EP-05-S03 | D22: As a Client, I want to view the approved floor plan and submit revision comments, so that I can confirm the layout before the event. | E22: 1. PASS: Client can view the approved floor plan snapshot from within the client portal after PMCM Admin publishes it (EP-05-S01 gate). 2. PASS: Client view is read-only; client cannot edit or mutate the official floor plan in any way. 3. PASS: Client can submit revision comments on the published floor plan; comments are routed to PMCM Admin for review. 4. PASS: Only the designated primary client contact can submit revision comments; non-primary contacts have read-only access. 5. PASS: Floor plan is locked once approved by PMCM Admin; no further client revision comments are accepted after approval. 6. PASS: Supplier, coordinator, and guest actors cannot access the client floor plan view or revision comments. 7. FAIL trigger: Client can mutate official floor plan state, non-primary client contacts can submit revision comments, floor plan remains open for revision after PMCM Admin approval, or non-authorized actors can access floor plan data. | F22: Must | G22: C (Ethan) | H22: To Do | I22: EP-05-S01 | J22: FR-29, FR-83; read-only official snapshot access; client annotations actionable only for designated primary contact; floor plan locked once approved. | K22: =IF(H22="Done",1,IF(H22="In Progress",0.5,IF(H22="In Review",0.75,0))) -> 0
A23: EP-05 | B23: Floor Plan and Venue | C23: EP-05-S04 | D23: As a PMCM Admin, I want a floor plan canvas editor with a draggable element library, so that I can draw and adjust venue layouts using interactive tools. | E23: 1. 1. PASS: Floor plan canvas editor is accessible to PMCM Admin from within apps/event; editor uses a custom native HTML5 Canvas renderer for canvas interaction (confirmed implementation choice; supersedes original Konva.js/Fabric.js planning note). 2. PASS: Pre-built draggable elements library is available by category (e.g., tables, chairs, stage, podium, AV equipment); elements are draggable onto the canvas. 3. PASS: Canvas editor persistence shape is unchanged from pre-extraction behavior; no regression is introduced to existing canvas save and load behavior. 4. PASS: PMCM Admin can save, reload, and update the canvas state; saved state is retrievable per event. 5. PASS: Editor is accessible only to PMCM Admin; client, supplier, coordinator, and guest actors cannot access the canvas editor. 6. N/A, out of scope: "Venue Styling" and decor/moodboard workflows (FR-09, FR-15, FR-43) exist only in Phase 2 planning documentation with zero implementation in this codebase. This AC describes SB-14 (Venue Styling Hard Dependency Lock), a Change Enablement Engine sub-ticket concern that belongs to a future epic, not the floor plan canvas editor. No action required here until that epic is built. 7. FAIL trigger: Canvas editor is accessible to non-PMCM actors, pre-built elements library is absent, canvas persistence behavior regresses from pre-extraction state, or styling sub-tickets proceed before floor plan approval. | F23: Must | G23: B (Francis) | H23: In Review | I23: None | J23: FR-80; Konva.js or Fabric.js; pre-built draggable elements by category; canvas/editor persistence shape unchanged. Sub-ticket hard dependency confirmed -- styling blocked until floor plan approved. | K23: =IF(H23="Done",1,IF(H23="In Progress",0.5,IF(H23="In Review",0.75,0))) -> 0.75
A24: EP-06 -- Compliance and Change Enablement
A25: EP-06 | B25: Compliance and Change Enablement | C25: EP-06-S01 | D25: As a PMCM Admin, I want the system to validate event requirements against compliance rules, so that no required item is missed before the event. | E25: 1. PASS: Compliance validation is accessible to PMCM Admin from within apps/event after conforme is signed (EP-04-S01 gate). 2. PASS: Compliance Engine performs rule-based field-presence validation: it checks whether required fields and documents are present per defined compliance rules, not semantic analysis of content. NLP = benchmark only (89.1% precision, Abualhaija et al. 2023); this must not be overstated in any AC or documentation. 3. PASS: Compliance rules are managed by ComplianceWorkflowService inside compliance-ops via COMPLIANCE_COMMANDS port; rules are stored per event type or per event. 4. PASS: Validation results are returned via COMPLIANCE_READER port; results distinguish between Must-Fix Items (blocking) and Advisory Items (non-blocking). 5. PASS: PMCM Admin can view the full compliance validation result per event, including which specific rules passed and which failed. 6. PASS: AI advisory layer (FR-10+) is explicitly not part of this story; no AI-generated compliance suggestions are present here. AI advisory is Phase 2 scope gated on EP-15-S05. 7. PASS: Supplier, coordinator, client, and guest actors cannot access compliance rule definitions or validation results. 8. PASS: Compliance validation result feeds the defense and readiness gate (EP-06-S02); EP-06-S02 cannot be attempted until at minimum one compliance validation run has been recorded. 9. FAIL trigger: Compliance Engine performs semantic NLP analysis rather than field-presence validation, AI advisory layer is present in this story scope, validation results are accessible to non-PMCM actors, or COMPLIANCE_READER and COMPLIANCE_COMMANDS ports are bypassed by direct Prisma calls. | F25: Must | G25: B (Francis) | H25: To Do | I25: EP-04-S01 | J25: FR-06; compliance-ops; ComplianceWorkflowService; three-layer architecture. NLP = benchmark only -- critical rule. AI advisory (FR-10+) is Phase 2 scope only. | K25: =IF(H25="Done",1,IF(H25="In Progress",0.5,IF(H25="In Review",0.75,0))) -> 0
A26: EP-06 | B26: Compliance and Change Enablement | C26: EP-06-S02 | D26: As a PMCM Admin, I want a defense and readiness gate check, so that I can confirm all pre-event conditions are met before approving event execution. | E26: 1. PASS: Defense and readiness gate check is accessible to PMCM Admin from within apps/event; not accessible to client, supplier, coordinator, or guest actors. 2. PASS: Gate check is handled by defenseReadiness composition inside compliance-ops; it aggregates compliance validation results, supplier confirmation status, payment milestone status, and floor plan approval status into a single readiness report. 3. PASS: Pre-Event Readiness Report is generated and displays: overall readiness status (Ready or Not Ready), a list of all Must-Fix Items blocking readiness, and a list of all Advisory Items not blocking readiness. 4. PASS: Event is flagged as Not Ready until all Must-Fix Items are resolved; PMCM Admin cannot mark an event as approved for execution while Must-Fix Items remain. 5. PASS: Each resolved Must-Fix Item is recorded with timestamp and resolving admin identity in the audit trail. 6. PASS: Pre-Event Readiness Report is retrievable per event; historical readiness runs are stored, not overwritten. 7. PASS: Client, supplier, coordinator, and guest actors cannot access the Pre-Event Readiness Report or defenseReadiness composition results. 8. FAIL trigger: Event can be approved for execution with open Must-Fix Items, defenseReadiness composition is accessible to non-PMCM actors, readiness report is overwritten rather than stored per run, or Must-Fix Item resolution is not recorded in audit trail. | F26: Must | G26: B (Francis) | H26: To Do | I26: EP-06-S01 | J26: FL-015; compliance-ops; defenseReadiness composition; client/guest denied. Pre-Event Readiness Report generated. | K26: =IF(H26="Done",1,IF(H26="In Progress",0.5,IF(H26="In Review",0.75,0))) -> 0
A27: EP-06 | B27: Compliance and Change Enablement | C27: EP-06-S03 | D27: As a PMCM Admin, I want to raise and classify change requests and enforce the change freeze window, so that all changes are audited and no unauthorized scope changes occur within 5 days of the event. | E27: 1. PASS: PMCM Admin can raise a change request from within apps/event after conforme is signed; change request captures: change type, description, requester, classification (Standard, Emergency, or Operational Adjustment), and affected event. 2. PASS: Change freeze is automatically enforced at exactly 5 days before the event date; client scope changes are locked after the freeze window opens. 3. PASS: Internal operational adjustments by PMCM Admin are always permitted regardless of freeze window status. 4. PASS: Emergency Change classification is available during the freeze window for PMCM Admin; Emergency Changes require explicit classification and produce an audit log entry. 5. PASS: Supplier withdrawal within the freeze window automatically triggers Emergency Change classification and activates the PARE flow (EP-12-S02 dependency). 6. PASS: All change requests are recorded in the audit trail with timestamp, classifying admin identity, and classification rationale. 7. PASS: Change request history is retrievable per event by PMCM Admin; client can view their own submitted change requests but cannot view PMCM internal change request records. 8. PASS: Supplier, coordinator, and guest actors cannot raise or view change requests. 9. FAIL trigger: Change freeze is not enforced at exactly 5 days before event, client scope changes are accepted after freeze window opens, Emergency Change is available to non-PMCM actors, or change requests are not recorded in audit trail. | F27: Must | G27: B (Francis) | H27: To Do | I27: EP-04-S01 | J27: New-SY3; CE rule engine and freeze enforcement only. Change freeze = 5 days before event. EP-12-S02 (PARE) and EP-12-S03 (supplier withdrawal) both depend on this story. | K27: =IF(H27="Done",1,IF(H27="In Progress",0.5,IF(H27="In Review",0.75,0))) -> 0
A28: EP-07 -- Supplier Network and Readiness
A29: EP-07 | B29: Supplier Network and Readiness | C29: EP-07-S01 | D29: As a PMCM Admin, I want to manage a supplier directory with category tagging, reliability notes, and certifications, so that I can select the best supplier per category. | E29: 1. PASS: Supplier directory is accessible to PMCM Admin from apps/event and displays all registered suppliers. 2. PASS: Each supplier record includes: supplier name, assigned category (one of 8 confirmed: Production, Technicals, Digital Registration, Documentation, Food and Beverages, Talents, Logistics, Program and Manpower), Tier designation (Tier 1 or Tier 2), BNI Member flag, and Pending First Event status for newly approved suppliers. 3. PASS: PMCM Admin can add reliability notes to a supplier record; notes are stored and retrievable on subsequent views. 4. PASS: PMCM Admin can attach certifications to a supplier record. 5. PASS: Aggregate review rating is visible on the supplier record to PMCM Admin only; not exposed to supplier, client, guest, or coordinator actors. 6. PASS: BNI Member flag is toggleable by PMCM Admin and persists on the record. 7. PASS: Supplier directory is filterable or searchable by at minimum category and tier designation. 8. PASS: Supplier, client, guest, and coordinator actors cannot access the supplier directory or any supplier record detail payload. 9. FAIL trigger: Any of the 8 supplier categories is absent, aggregate review rating is visible to non-PMCM actors, BNI flag does not persist, reliability notes are not stored, or non-PMCM actors can access directory data. | F29: Must | G29: B (Francis) | H29: Done | I29: None | J29: FR-14, FR-35; confirmed Live per File 9. BNI member flag; aggregate review rating PMCM-only; 8 confirmed categories. | K29: =IF(H29="Done",1,IF(H29="In Progress",0.5,IF(H29="In Review",0.75,0))) -> 1
A30: EP-07 | B30: Supplier Network and Readiness | C30: EP-07-S02 | D30: As a PMCM Admin, I want to send quote requests to Tier 1 and Tier 2 suppliers per category, so that I have competitive quotes before confirming suppliers. | E30: 1. PASS: PMCM Admin can send a quote request to Tier 1 and Tier 2 suppliers for any of the 8 supplier categories independently. 2. PASS: Quote request includes at minimum: event details, required service scope, and submission deadline. 3. PASS: Supplier receives notification of the quote request. 4. PASS: Supplier can submit one revision to their quote before the deadline; a second revision attempt after the first revision is blocked with a clear message. 5. PASS: Quote is locked and no further supplier edits are permitted after PMCM Admin selects the supplier. 6. PASS: PMCM Admin can view all received quotes for a category side by side before making a selection. 7. PASS: Quote request record is stored and retrievable in supplier-ops module; no quote data is exposed to client, guest, or coordinator actors. 8. FAIL trigger: Quote revision limit is not enforced, quote remains editable after supplier selection, quote data is accessible to non-PMCM or non-supplier actors, or quote request record is not persisted. | F30: Must | G30: B (Francis) | H30: Done | I30: EP-07-S01 | J30: FR-17; confirmed Live per File 9. One revision allowed before deadline. Quote locked after supplier selected. | K30: =IF(H30="Done",1,IF(H30="In Progress",0.5,IF(H30="In Review",0.75,0))) -> 1
A31: EP-07 | B31: Supplier Network and Readiness | C31: EP-07-S03 | D31: As a Supplier, I want to review and confirm my availability and quote, so that PMCM can formally assign me to the event. | E31: 1. PASS: Supplier can view the full quote request details sent by PMCM Admin inside the supplier portal (apps/supplier, port 3002). 2. PASS: Supplier must explicitly confirm availability and review and accept the quoted terms before formal assignment is recorded. 3. PASS: Supplier confirmation triggers a status update visible to PMCM Admin on the quote request record. 4. PASS: No raw AI output is shown to the supplier at any point in this flow; all supplier-facing communications are PMCM-reviewed before sending (FR-AI-04b). 5. PASS: Supplier can only view and act on their own quote requests; they cannot access quote requests sent to other suppliers for the same event or category. 6. PASS: Formal assignment is only recorded after supplier confirmation is received; PMCM Admin cannot mark a supplier as assigned without supplier confirmation on record. 7. PASS: Supplier actor cannot access client data, coordinator data, or PMCM internal cost or planning data at any point in this flow. 8. FAIL trigger: Supplier is formally assigned without their explicit confirmation, raw AI output is surfaced to the supplier, supplier can view another supplier quote request, or supplier can access non-supplier data payloads. | F31: Must | G31: C (Ethan) | H31: Done | I31: EP-07-S02 | J31: FR-37; confirmed Live per File 9. No raw AI output to suppliers -- critical role boundary. | K31: =IF(H31="Done",1,IF(H31="In Progress",0.5,IF(H31="In Review",0.75,0))) -> 1
A32: EP-07 | B32: Supplier Network and Readiness | C32: EP-07-S04 | D32: As a PMCM Admin, I want to send a pre-event readiness confirmation request to each supplier 7 days before the event, so that last-minute issues are caught before event day. | E32: 1. PASS: System triggers a readiness confirmation request to each confirmed supplier exactly 7 days before the event date without requiring manual PMCM Admin initiation. 2. PASS: Readiness confirmation request presents the supplier with a one-tap confirmation action. 3. PASS: Supplier confirms readiness with a one-tap yes/no action. If confirming with a concern, supplier can optionally add a free-text note visible to PMCM Admin only. FR-64 full communication thread is Phase 2 scope and is not part of this story. [PA-77 RESOLVED] 4. PASS: PMCM Admin receives a consolidated readiness status per event showing which suppliers have confirmed and which have not responded. 5. PASS: Suppliers who have not responded by 48 hours before the event are flagged with a clear alert on the PMCM command surface. 6. PASS: Readiness confirmation records are stored per supplier per event and feed the Pre-Event Readiness Report (EP-06-S02). 7. PASS: Supplier confirmation is visible only to PMCM Admin; client, coordinator, and guest actors cannot access supplier readiness records. 8. FAIL trigger: Readiness request is not triggered automatically at 7 days, unresponsive supplier is not flagged at 48 hours, readiness records are accessible to non-PMCM actors, or confirmation record does not feed EP-06-S02. | F32: Must | G32: B (Francis) | H32: To Do | I32: EP-07-S03 | J32: New-SUP2; FL-022; PA-77 RESOLVED -- concern flagging via optional free-text note (Prism scope); FR-64 full communication thread is Phase 2 scope only. | K32: =IF(H32="Done",1,IF(H32="In Progress",0.5,IF(H32="In Review",0.75,0))) -> 0
A33: EP-07 | B33: Supplier Network and Readiness | C33: EP-07-S05 | D33: As a Supplier, I want to update my on-site arrival and setup status during the event, so that PMCM can track supplier presence in real time. | E33: 1. PASS: Supplier can update their on-site status from within the supplier portal (apps/supplier) during the event using exactly three status buttons: Arrived, Set Up and Ready, Done and Leaving. 2. PASS: Supplier can attach an optional photo to each status update; photo upload is optional, not required, for the status to be recorded. 3. PASS: Each status update is recorded with timestamp and supplier identity; updates are visible to PMCM Admin in real time on the live operations dashboard (EP-12-S01). 4. PASS: Each status update carries one of two verification levels: Self-Reported (supplier own update) or Verified. [PLACEHOLDER: confirm which role performs Verified level and through which surface -- PA-76 OPEN. Ms. Mys must confirm.] 5. PASS: Supplier can only update their own event status; they cannot view or update status records for other suppliers assigned to the same event. 6. PASS: Client, coordinator, and guest actors cannot access or update supplier status records. 7. FAIL trigger: Status buttons are not exactly three, status updates are not visible in real time on PMCM live ops dashboard, supplier can update another supplier status, or non-supplier non-PMCM actors can access supplier status data. | F33: Must | G33: C (Ethan) | H33: Done | I33: EP-07-S03 | J33: New-SUP1; confirmed Live per File 9. PA-76 OPEN -- Ms. Mys must confirm who performs Verified level and through which surface. ACTION: Ask Ms. Mys. | K33: =IF(H33="Done",1,IF(H33="In Progress",0.5,IF(H33="In Review",0.75,0))) -> 1
A34: EP-07 | B34: Supplier Network and Readiness | C34: EP-07-S06 | D34: As a PMCM Admin or prospective Supplier, I want to register a new supplier on the platform, so that they can be added to the active supplier network. | E34: 1. PASS: A public-facing supplier registration form is accessible without login or account creation. 2. PASS: Registration form captures at minimum: supplier name, primary contact name, contact number, email address, service category (one of the 8 confirmed categories), and a brief description of services. 3. PASS: BNI Member toggle is available on the registration form and the selected value is stored on the supplier application record. 4. PASS: Submitted application is routed to the Supplier Applications inbox in PMCM Admin (EP-07-S09). 5. PASS: Applicant receives a confirmation acknowledgment on submission. 6. PASS: Submitted application is not automatically approved; PMCM Admin must take explicit action on each application (EP-07-S09). 7. PASS: Supplier, client, guest, and coordinator actors with existing accounts cannot submit a second registration through this form without PMCM Admin awareness. 8. FAIL trigger: Registration form requires login or account creation, BNI Member toggle is absent, submitted application is not routed to PMCM Admin inbox, or application is automatically approved without PMCM Admin action. | F34: Must | G34: C (Ethan) | H34: To Do | I34: None | J34: New-SUP3 = New-EX1 = New-S1; PA-74 OPEN -- canonical FR number and name TBD. One story only. Public-facing application form. Routes to EP-07-S09 (Supplier Applications inbox). | K34: =IF(H34="Done",1,IF(H34="In Progress",0.5,IF(H34="In Review",0.75,0))) -> 0
A35: EP-07 | B35: Supplier Network and Readiness | C35: EP-07-S07 | D35: As Ms. Mys or EA, I want to review each assigned supplier after an event is closed, so that performance ratings are recorded privately and inform future tier decisions. | E35: 1. PASS: Ms. Mys and EA can access the Internal Supplier Review surface after an event is closed; no other actor can access this surface. 2. PASS: Review form captures: overall star rating (1 to 5) and category-specific dimension ratings per supplier. 3. PASS: A private notes field is available per supplier review; notes are stored and visible only to Ms. Mys and EA. 4. PASS: Review ratings are not visible to the reviewed supplier, other suppliers, clients, coordinators, or guest actors under any circumstance. 5. PASS: PA-71 must be resolved before Done: Ms. Mys must confirm EA full role name and whether EA has own system login or is a sub-role under PMCM Admin. 6. PASS: Review ratings feed EP-07-S08 (tier decisions) and the Event Insights Card (EP-14-S01 New-P2). 7. FAIL trigger: Any actor other than Ms. Mys and EA can access the Internal Supplier Review surface, ratings are visible to the reviewed supplier, or PA-71 is unresolved at Done call. | F35: Must | G35: B (Francis) | H35: Done | I35: None | J35: New-S5; confirmed Live per File 9. PA-71 OPEN -- Ms. Mys must confirm EA full role name and login type. ACTION: Ask Ms. Mys. | K35: =IF(H35="Done",1,IF(H35="In Progress",0.5,IF(H35="In Review",0.75,0))) -> 1
A36: EP-07 | B36: Supplier Network and Readiness | C36: EP-07-S08 | D36: As a PMCM Admin, I want to assess supplier performance across multiple events and manually adjust their tier designation, so that the supplier network reflects real reliability history. | E36: 1. PASS: PMCM Admin can view accumulated post-event review ratings per supplier across multiple events from within apps/event. 2. PASS: PMCM Admin can manually upgrade or downgrade a supplier tier designation (Tier 1 or Tier 2) based on accumulated review data. 3. PASS: Tier change is recorded with timestamp, acting admin identity, and rationale in the audit trail. 4. PASS: Tier change is reflected immediately on the supplier directory record (EP-07-S01). 5. PASS: Supplier is not notified of internal tier assessment or tier change decision. 6. PASS: Client, coordinator, and guest actors cannot access supplier tier assessment data. 7. FAIL trigger: Tier change is not recorded in audit trail, tier change is not reflected on supplier directory, or supplier is notified of internal tier decision. | F36: Should | G36: B (Francis) | H36: To Do | I36: EP-07-S07 | J36: New-S4; post-event review ratings from New-S5 accumulate before tier decisions. Manual tier upgrade or downgrade by PMCM. Informed by PMCM Internal Supplier Review ratings. | K36: =IF(H36="Done",1,IF(H36="In Progress",0.5,IF(H36="In Review",0.75,0))) -> 0
A37: EP-07 | B37: Supplier Network and Readiness | C37: EP-07-S09 | D37: As a PMCM Admin, I want to review incoming supplier applications and take action on each one, so that prospective suppliers are assessed and added to the network in a controlled process. | E37: 1. PASS: PMCM Admin can access the Supplier Applications inbox from within apps/event; inbox displays all submitted supplier applications. 2. PASS: PMCM Admin can take one of three actions per application: Request Proposal, Schedule Meeting, or Decline. 3. PASS: Approved suppliers (after proposal or meeting) are added to the supplier directory with Pending First Event status (New-S3). 4. PASS: Declined applicants receive a notification of the decision; the declined record is stored with decline reason. 5. PASS: Each action taken on an application produces an audit log entry with timestamp and acting admin identity. 6. PASS: Supplier application data is not accessible to client, coordinator, or guest actors. 7. FAIL trigger: PMCM Admin cannot take action on an application, approved supplier is not added with Pending First Event status, or application data is accessible to non-PMCM actors. | F37: Should | G37: B (Francis) | H37: To Do | I37: EP-07-S06 | J37: New-S2; three action options: Request Proposal, Schedule Meeting, Decline. Approved suppliers added with Pending First Event status (New-S3). Feeds EP-07-S10. | K37: =IF(H37="Done",1,IF(H37="In Progress",0.5,IF(H37="In Review",0.75,0))) -> 0
A38: EP-07 | B38: Supplier Network and Readiness | C38: EP-07-S10 | D38: As a prospective Supplier, I want to check the status of my application after submitting, so that I know where I stand in the onboarding process without contacting PMCM directly. | E38: 1. PASS: Prospective supplier can access a lightweight status page (no full portal login required) to check their application status. 2. PASS: Status page displays one of five statuses: Under Review, Proposal Requested, Meeting Scheduled, Approved, Declined. 3. PASS: Status updates are triggered by PMCM Admin actions in EP-07-S09; status page reflects the current action state without delay. 4. PASS: A confirmation email is sent to the applicant on initial submission (EP-07-S06 trigger). 5. PASS: Status page does not expose other applicant data, internal PMCM notes, or supplier directory data. 6. FAIL trigger: Status page requires full portal login, fewer or more than five statuses are displayed, status does not reflect PMCM Admin actions from EP-07-S09, or internal PMCM data is exposed on the status page. | F38: Should | G38: C (Ethan) | H38: To Do | I38: EP-07-S09 | J38: New-SUP4; five statuses: Under Review, Proposal Requested, Meeting Scheduled, Approved, Declined. Confirmation email sent on submission. Coordinate with Francis (Owner B) on status update triggers from PMCM inbox actions. | K38: =IF(H38="Done",1,IF(H38="In Progress",0.5,IF(H38="In Review",0.75,0))) -> 0
A39: EP-08 -- Finance and Billing
A40: EP-08 | B40: Finance and Billing | C40: EP-08-S01 | D40: As a PMCM Admin, I want a billing statement generated automatically when conforme is signed, so that the 50% downpayment milestone is tracked and invoiced immediately. | E40: 1. PASS: Billing statement is generated automatically on successful conforme upload (EP-04-S01 gate); no manual PMCM Admin action is required to trigger billing statement generation. 2. PASS: Billing statement is handled by BillingOperationsService inside finance-ops. 3. PASS: Generated billing statement includes the 50% downpayment milestone as the first payment record. 4. PASS: recordPayment idempotency guard is enforced; a duplicate conforme upload event does not generate a second billing statement. 5. PASS: Billing statement is retrievable per event by PMCM Admin; not accessible to supplier, coordinator, or guest actors. 6. PASS: PA-109 must be resolved before Done: Anthony must confirm whether uploadConforme calls billing logic directly or routes through FinanceOpsModule. 7. FAIL trigger: Billing statement is not generated automatically on conforme upload, duplicate conforme event generates a second billing statement, billing statement is accessible to non-PMCM non-client actors, or PA-109 is unresolved at Done call. | F40: Must | G40: D (Anthony) | H40: To Do | I40: EP-04-S01 | J40: FR-20; finance-ops; BillingOperationsService; conforme triggers billing. PA-109 OPEN -- Anthony must confirm uploadConforme billing path routing before Done call. ACTION: Anthony to resolve PA-109. | K40: =IF(H40="Done",1,IF(H40="In Progress",0.5,IF(H40="In Review",0.75,0))) -> 0
...

Sheet Dashboard
A1: P.R.I.S.M. AC TRACKER -- SYSTEM DASHBOARD
A2: Overall System Completion %
A3: =(COUNTIF(Tracker!H:H,"Done")*100+COUNTIF(Tracker!H:H,"In Progress")*50+COUNTIF(Tracker!H:H,"In Review")*75)/MAX(1,COUNTIF(Tracker!C:C,"EP-*")) -> 28.333333
A5: Completion by Cadence
A6: C1 | B6: C2 | C6: C3 | D6: C4
A7: =(COUNTIFS(#REF!,"C1",Tracker!H:H,"Done")*100+COUNTIFS(#REF!,"C1",Tracker!H:H,"In Progress")*50+COUNTIFS(#REF!,"C1",Tracker!H:H,"In Review")*75)/MAX(1,COUNTIF(#REF!,"C1")) -> #VALUE! | B7: =(COUNTIFS(#REF!,"C2",Tracker!H:H,"Done")*100+COUNTIFS(#REF!,"C2",Tracker!H:H,"In Progress")*50+COUNTIFS(#REF!,"C2",Tracker!H:H,"In Review")*75)/MAX(1,COUNTIF(#REF!,"C2")) -> #VALUE! | C7: =(COUNTIFS(#REF!,"C3",Tracker!H:H,"Done")*100+COUNTIFS(#REF!,"C3",Tracker!H:H,"In Progress")*50+COUNTIFS(#REF!,"C3",Tracker!H:H,"In Review")*75)/MAX(1,COUNTIF(#REF!,"C3")) -> #VALUE! | D7: =(COUNTIFS(#REF!,"C4",Tracker!H:H,"Done")*100+COUNTIFS(#REF!,"C4",Tracker!H:H,"In Progress")*50+COUNTIFS(#REF!,"C4",Tracker!H:H,"In Review")*75)/MAX(1,COUNTIF(#REF!,"C4")) -> #VALUE!
A9: Stories by Status
A10: Done | B10: In Progress | C10: In Review | D10: To Do | E10: Blocked
A11: =COUNTIF(Tracker!H:H,"Done") -> 17 | B11: =COUNTIF(Tracker!H:H,"In Progress") -> 7 | C11: =COUNTIF(Tracker!H:H,"In Review") -> 1 | D11: =COUNTIF(Tracker!H:H,"To Do") -> 46 | E11: =COUNTIF(Tracker!H:H,"Blocked") -> 4
A13: Completion by Owner -- Done / In Progress / Total and Weighted %
A14: Owner | B14: Person | C14: Done | D14: In Progress | E14: Total Stories | F14: Completion %
A15: A (Maxine) | B15: Maxine | C15: =COUNTIFS(Tracker!G:G,"A (Maxine)",Tracker!H:H,"Done") -> 0 | D15: =COUNTIFS(Tracker!G:G,"A (Maxine)",Tracker!H:H,"In Progress") -> 1 | E15: =COUNTIF(Tracker!G:G,"A (Maxine)") & " stories" -> 2 stories | F15: =(COUNTIFS(Tracker!G:G,"A (Maxine)",Tracker!H:H,"Done")*100+COUNTIFS(Tracker!G:G,"A (Maxine)",Tracker!H:H,"In Progress")*50)/MAX(1,COUNTIF(Tracker!G:G,"A (Maxine)")) -> 25
A16: B (Francis) | B16: Francis | C16: =COUNTIFS(Tracker!G:G,"B (Francis)",Tracker!H:H,"Done") -> 9 | D16: =COUNTIFS(Tracker!G:G,"B (Francis)",Tracker!H:H,"In Progress") -> 4 | E16: =COUNTIF(Tracker!G:G,"B (Francis)") & " stories" -> 36 stories | F16: =(COUNTIFS(Tracker!G:G,"B (Francis)",Tracker!H:H,"Done")*100+COUNTIFS(Tracker!G:G,"B (Francis)",Tracker!H:H,"In Progress")*50)/MAX(1,COUNTIF(Tracker!G:G,"B (Francis)")) -> 30.555556
A17: C (Ethan) | B17: Ethan | C17: =COUNTIFS(Tracker!G:G,"C (Ethan)",Tracker!H:H,"Done") -> 4 | D17: =COUNTIFS(Tracker!G:G,"C (Ethan)",Tracker!H:H,"In Progress") -> 2 | E17: =COUNTIF(Tracker!G:G,"C (Ethan)") & " stories" -> 16 stories | F17: =(COUNTIFS(Tracker!G:G,"C (Ethan)",Tracker!H:H,"Done")*100+COUNTIFS(Tracker!G:G,"C (Ethan)",Tracker!H:H,"In Progress")*50)/MAX(1,COUNTIF(Tracker!G:G,"C (Ethan)")) -> 31.25
A18: D (Anthony) | B18: Anthony | C18: =COUNTIFS(Tracker!G:G,"D (Anthony)",Tracker!H:H,"Done") -> 4 | D18: =COUNTIFS(Tracker!G:G,"D (Anthony)",Tracker!H:H,"In Progress") -> 0 | E18: =COUNTIF(Tracker!G:G,"D (Anthony)") & " stories" -> 21 stories | F18: =(COUNTIFS(Tracker!G:G,"D (Anthony)",Tracker!H:H,"Done")*100+COUNTIFS(Tracker!G:G,"D (Anthony)",Tracker!H:H,"In Progress")*50)/MAX(1,COUNTIF(Tracker!G:G,"D (Anthony)")) -> 19.047619
A20: Stories by MoSCoW Priority -- Count and Completion
A21: Priority | B21: Total Stories | C21: Done | D21: In Progress | E21: Completion %
A22: Must | B22: =COUNTIF(Tracker!F:F,"Must") -> 51 | C22: =COUNTIFS(Tracker!F:F,"Must",Tracker!H:H,"Done") -> 15 | D22: =COUNTIFS(Tracker!F:F,"Must",Tracker!H:H,"In Progress") -> 7 | E22: =(COUNTIFS(Tracker!F:F,"Must",Tracker!H:H,"Done")*100+COUNTIFS(Tracker!F:F,"Must",Tracker!H:H,"In Progress")*50)/MAX(1,COUNTIF(Tracker!F:F,"Must")) -> 36.27451
