Workbook
Name RoleList: Lists!$A$2:$A$6
Name LevelList: Lists!$B$2:$B$5

Sheet Instructions
B1: P.R.I.S.M UAT Form - How to use
B3: Steps
A4: 1 | B4: Open the UAT Form sheet. Choose your role in "What is your user role?".
A5: 2 | B5: Choose one module in "What module would you test?". Only modules for your role are listed.
A6: 3 | B6: Enter your tester name and test date.
A7: 4 | B7: Do each test case and pick its Satisfaction Level.
A8: 5 | B8: For Partially Passed or Skipped, write a comment in the format: Test Case ID - Comment.
A9: 6 | B9: When Submission status shows READY TO SUBMIT, copy the Submission rows (J13:R18) and paste them as values into the next empty rows of Responses.
A10: 7 | B10: Clear the yellow cells and choose your next module. One submission per module.
B12: Satisfaction Level
B13: Passed - Working | C13: The test case works as expected.
B14: Partially Passed - Works but needs revision (w/ comment) | C14: It works but needs revision. A comment is required.
B15: Fail - Not working | C15: It does not work.
B16: Skipped - Di tinest (w/ comment) | C16: Not tested. A comment is required.
B18: Comment question
B19: IF YOU SELECT PARTIALLY PASSED OR SKIPPED Please may we know your suggestion or the part that need to improve STRICTLY
B20: Format: Test Case ID - Comment
B22: Legend
B23: Yellow cells | C23: Fill these in. Everything else is calculated.
B24: Grey cells | C24: Calculated. Do not type here.
B26: Example (Client, CL-INQ · Public Inquiry)
B27: CL-INQ-01 - Open the inquiry form | C27: Passed - Working
B28: CL-INQ-02 - Required contact details | C28: Partially Passed - Works but needs revision (w/ comment) | D28: CL-INQ-02 - No message appears when a required field is blank
B29: CL-INQ-05 - Submit the inquiry | C29: Skipped - Di tinest (w/ comment) | D29: CL-INQ-05 - Did not test because the API was offline
B31: Sheets
B32: UAT Form | C32: Answer one module at a time.
B33: Test Cases | C33: All 197 test cases across 5 roles and 51 modules. Filter by role or module.
B34: Responses | C34: One row per test case result. Each module submission adds its rows here.
B35: Summary | C35: Results per role and module, calculated from Responses.

Sheet UAT Form
A1: P.R.I.S.M UAT Form
A2: Fill the yellow cells. One submission per module: after finishing, copy the Submission rows (columns J to R) into the Responses sheet, then clear the yellow cells and choose your next module.
A4: What is your user role?
A5: What module would you test?
A6: Tester name
A7: Test date
A8: Before you start | C8: =IF($C$5="","",IFERROR(INDEX('Test Cases'!$H:$H,MATCH($C$5,'Test Cases'!$C:$C,0)),""))
A9: Module check | C9: =IF(OR($C$4="",$C$5=""),"",IF(COUNTIFS(Lists!$D:$D,$C$4,Lists!$E:$E,$C$5)=0,"Module is not for the selected role","OK"))
A10: Submission status | C10: =IF(OR($C$4="",$C$5=""),"Choose your role and module",IF($C$9<>"OK","Module does not match role",IF(OR($C$6="",$C$7=""),"Enter tester name and test date",IF(COUNTIF($H$13:$H$18,"Not rated")+COUNTIF($H$13:$H$18,"Comment required")=0,"READY TO SUBMIT",COUNTIF($H$13:$H$18,"Not rated")&" not rated, "&COUNTIF($H$13:$H$18,"Comment required")&" comment(s) required"))))
J11: Submission rows: copy J13:R18, then Paste Special > Values into the next empty rows of Responses
A12: # | B12: Test Case ID | C12: Test Case | D12: Steps | E12: Expected Result | F12: Satisfaction Level | G12: Comment Format: Test Case ID - Comment | H12: Check | J12: Submission ID | K12: Test Date | L12: Tester | M12: User Role | N12: Module | O12: Test Case ID | P12: Test Case | Q12: Satisfaction Level | R12: Comment
A13: 1 | B13: =IF($C$9<>"OK","",IF(COUNTIF('Test Cases'!$C:$C,$C$5)>=$A13,INDEX('Test Cases'!$D:$D,MATCH($C$5,'Test Cases'!$C:$C,0)+$A13-1),"")) | C13: =IF($B13="","",INDEX('Test Cases'!$E:$E,MATCH($B13,'Test Cases'!$D:$D,0))) | D13: =IF($B13="","",INDEX('Test Cases'!$F:$F,MATCH($B13,'Test Cases'!$D:$D,0))) | E13: =IF($B13="","",INDEX('Test Cases'!$G:$G,MATCH($B13,'Test Cases'!$D:$D,0))) | H13: =IF($B13="","",IF($F13="","Not rated",IF(OR($F13=Lists!$B$3,$F13=Lists!$B$5),IF(AND(LEFT(SUBSTITUTE($G13," ",""),LEN($B13)+1)=$B13&"-",LEN(SUBSTITUTE($G13," ",""))>LEN($B13)+1),"OK","Comment required"),"OK"))) | J13: =IF($B13="","",LEFT($C$5,FIND(" ",$C$5)-1)&"-"&TEXT($C$7,"yyyymmdd")&"-"&$C$6) | K13: =IF($B13="","",$C$7) | L13: =IF($B13="","",$C$6) | M13: =IF($B13="","",$C$4) | N13: =IF($B13="","",$C$5) | O13: =IF($B13="","",$B13) | P13: =IF($B13="","",$C13) | Q13: =IF($B13="","",IF($F13="","",$F13)) | R13: =IF($B13="","",IF($G13="","",$G13))
A14: 2 | B14: =IF($C$9<>"OK","",IF(COUNTIF('Test Cases'!$C:$C,$C$5)>=$A14,INDEX('Test Cases'!$D:$D,MATCH($C$5,'Test Cases'!$C:$C,0)+$A14-1),"")) | C14: =IF($B14="","",INDEX('Test Cases'!$E:$E,MATCH($B14,'Test Cases'!$D:$D,0))) | D14: =IF($B14="","",INDEX('Test Cases'!$F:$F,MATCH($B14,'Test Cases'!$D:$D,0))) | E14: =IF($B14="","",INDEX('Test Cases'!$G:$G,MATCH($B14,'Test Cases'!$D:$D,0))) | H14: =IF($B14="","",IF($F14="","Not rated",IF(OR($F14=Lists!$B$3,$F14=Lists!$B$5),IF(AND(LEFT(SUBSTITUTE($G14," ",""),LEN($B14)+1)=$B14&"-",LEN(SUBSTITUTE($G14," ",""))>LEN($B14)+1),"OK","Comment required"),"OK"))) | J14: =IF($B14="","",LEFT($C$5,FIND(" ",$C$5)-1)&"-"&TEXT($C$7,"yyyymmdd")&"-"&$C$6) | K14: =IF($B14="","",$C$7) | L14: =IF($B14="","",$C$6) | M14: =IF($B14="","",$C$4) | N14: =IF($B14="","",$C$5) | O14: =IF($B14="","",$B14) | P14: =IF($B14="","",$C14) | Q14: =IF($B14="","",IF($F14="","",$F14)) | R14: =IF($B14="","",IF($G14="","",$G14))
A15: 3 | B15: =IF($C$9<>"OK","",IF(COUNTIF('Test Cases'!$C:$C,$C$5)>=$A15,INDEX('Test Cases'!$D:$D,MATCH($C$5,'Test Cases'!$C:$C,0)+$A15-1),"")) | C15: =IF($B15="","",INDEX('Test Cases'!$E:$E,MATCH($B15,'Test Cases'!$D:$D,0))) | D15: =IF($B15="","",INDEX('Test Cases'!$F:$F,MATCH($B15,'Test Cases'!$D:$D,0))) | E15: =IF($B15="","",INDEX('Test Cases'!$G:$G,MATCH($B15,'Test Cases'!$D:$D,0))) | H15: =IF($B15="","",IF($F15="","Not rated",IF(OR($F15=Lists!$B$3,$F15=Lists!$B$5),IF(AND(LEFT(SUBSTITUTE($G15," ",""),LEN($B15)+1)=$B15&"-",LEN(SUBSTITUTE($G15," ",""))>LEN($B15)+1),"OK","Comment required"),"OK"))) | J15: =IF($B15="","",LEFT($C$5,FIND(" ",$C$5)-1)&"-"&TEXT($C$7,"yyyymmdd")&"-"&$C$6) | K15: =IF($B15="","",$C$7) | L15: =IF($B15="","",$C$6) | M15: =IF($B15="","",$C$4) | N15: =IF($B15="","",$C$5) | O15: =IF($B15="","",$B15) | P15: =IF($B15="","",$C15) | Q15: =IF($B15="","",IF($F15="","",$F15)) | R15: =IF($B15="","",IF($G15="","",$G15))
A16: 4 | B16: =IF($C$9<>"OK","",IF(COUNTIF('Test Cases'!$C:$C,$C$5)>=$A16,INDEX('Test Cases'!$D:$D,MATCH($C$5,'Test Cases'!$C:$C,0)+$A16-1),"")) | C16: =IF($B16="","",INDEX('Test Cases'!$E:$E,MATCH($B16,'Test Cases'!$D:$D,0))) | D16: =IF($B16="","",INDEX('Test Cases'!$F:$F,MATCH($B16,'Test Cases'!$D:$D,0))) | E16: =IF($B16="","",INDEX('Test Cases'!$G:$G,MATCH($B16,'Test Cases'!$D:$D,0))) | H16: =IF($B16="","",IF($F16="","Not rated",IF(OR($F16=Lists!$B$3,$F16=Lists!$B$5),IF(AND(LEFT(SUBSTITUTE($G16," ",""),LEN($B16)+1)=$B16&"-",LEN(SUBSTITUTE($G16," ",""))>LEN($B16)+1),"OK","Comment required"),"OK"))) | J16: =IF($B16="","",LEFT($C$5,FIND(" ",$C$5)-1)&"-"&TEXT($C$7,"yyyymmdd")&"-"&$C$6) | K16: =IF($B16="","",$C$7) | L16: =IF($B16="","",$C$6) | M16: =IF($B16="","",$C$4) | N16: =IF($B16="","",$C$5) | O16: =IF($B16="","",$B16) | P16: =IF($B16="","",$C16) | Q16: =IF($B16="","",IF($F16="","",$F16)) | R16: =IF($B16="","",IF($G16="","",$G16))
A17: 5 | B17: =IF($C$9<>"OK","",IF(COUNTIF('Test Cases'!$C:$C,$C$5)>=$A17,INDEX('Test Cases'!$D:$D,MATCH($C$5,'Test Cases'!$C:$C,0)+$A17-1),"")) | C17: =IF($B17="","",INDEX('Test Cases'!$E:$E,MATCH($B17,'Test Cases'!$D:$D,0))) | D17: =IF($B17="","",INDEX('Test Cases'!$F:$F,MATCH($B17,'Test Cases'!$D:$D,0))) | E17: =IF($B17="","",INDEX('Test Cases'!$G:$G,MATCH($B17,'Test Cases'!$D:$D,0))) | H17: =IF($B17="","",IF($F17="","Not rated",IF(OR($F17=Lists!$B$3,$F17=Lists!$B$5),IF(AND(LEFT(SUBSTITUTE($G17," ",""),LEN($B17)+1)=$B17&"-",LEN(SUBSTITUTE($G17," ",""))>LEN($B17)+1),"OK","Comment required"),"OK"))) | J17: =IF($B17="","",LEFT($C$5,FIND(" ",$C$5)-1)&"-"&TEXT($C$7,"yyyymmdd")&"-"&$C$6) | K17: =IF($B17="","",$C$7) | L17: =IF($B17="","",$C$6) | M17: =IF($B17="","",$C$4) | N17: =IF($B17="","",$C$5) | O17: =IF($B17="","",$B17) | P17: =IF($B17="","",$C17) | Q17: =IF($B17="","",IF($F17="","",$F17)) | R17: =IF($B17="","",IF($G17="","",$G17))
A18: 6 | B18: =IF($C$9<>"OK","",IF(COUNTIF('Test Cases'!$C:$C,$C$5)>=$A18,INDEX('Test Cases'!$D:$D,MATCH($C$5,'Test Cases'!$C:$C,0)+$A18-1),"")) | C18: =IF($B18="","",INDEX('Test Cases'!$E:$E,MATCH($B18,'Test Cases'!$D:$D,0))) | D18: =IF($B18="","",INDEX('Test Cases'!$F:$F,MATCH($B18,'Test Cases'!$D:$D,0))) | E18: =IF($B18="","",INDEX('Test Cases'!$G:$G,MATCH($B18,'Test Cases'!$D:$D,0))) | H18: =IF($B18="","",IF($F18="","Not rated",IF(OR($F18=Lists!$B$3,$F18=Lists!$B$5),IF(AND(LEFT(SUBSTITUTE($G18," ",""),LEN($B18)+1)=$B18&"-",LEN(SUBSTITUTE($G18," ",""))>LEN($B18)+1),"OK","Comment required"),"OK"))) | J18: =IF($B18="","",LEFT($C$5,FIND(" ",$C$5)-1)&"-"&TEXT($C$7,"yyyymmdd")&"-"&$C$6) | K18: =IF($B18="","",$C$7) | L18: =IF($B18="","",$C$6) | M18: =IF($B18="","",$C$4) | N18: =IF($B18="","",$C$5) | O18: =IF($B18="","",$B18) | P18: =IF($B18="","",$C18) | Q18: =IF($B18="","",IF($F18="","",$F18)) | R18: =IF($B18="","",IF($G18="","",$G18))

Sheet Test Cases
A1: Role | B1: Module ID | C1: Module | D1: Test Case ID | E1: Test Case | F1: Steps | G1: Expected Result | H1: Before You Start
A2: Client | B2: CL-INQ | C2: CL-INQ · Public Inquiry | D2: CL-INQ-01 | E2: Open the inquiry form | F2: On the home page click Start inquiry. | G2: The inquiry form opens on step 1 (Contact Info) and the stepper shows 4 steps. | H2: Stay signed out. Open the client portal home page.
A3: Client | B3: CL-INQ | C3: CL-INQ · Public Inquiry | D3: CL-INQ-02 | E3: Required contact details | F3: Leave Full Name blank and click Continue. Then fill Full Name, Email, Phone, Client Type and Referral Source and click Continue. | G3: You cannot move on while a required field is blank. With all required fields filled you reach step 2 (Event Details). | H3: Stay signed out. Open the client portal home page.
A4: Client | B4: CL-INQ | C4: CL-INQ · Public Inquiry | D4: CL-INQ-03 | E4: Event details and date rules | F4: Try to pick a preferred date before today. Then fill Event Name, Event Type, a future Preferred Date and Expected Guests, and click Continue. | G4: Past dates cannot be picked. With valid details you reach step 3 (Budget & Notes). | H4: Stay signed out. Open the client portal home page.
A5: Client | B5: CL-INQ | C5: CL-INQ · Public Inquiry | D5: CL-INQ-04 | E5: Budget, priority and review | F5: Choose a budget range and an inquiry priority, click Continue, then click Back on step 4 and return. | G5: Step 4 shows a summary that matches what you entered. Back keeps your answers. | H5: Stay signed out. Open the client portal home page.
A6: Client | B6: CL-INQ | C6: CL-INQ · Public Inquiry | D6: CL-INQ-05 | E6: Submit the inquiry | F6: On step 4 try to submit without ticking the accuracy box, then tick it and submit. | G6: Submit stays disabled until the box is ticked. After submit a success screen with a reference number and Submit another inquiry appears. | H6: Stay signed out. Open the client portal home page.
A7: Client | B7: CL-ACC | C7: CL-ACC · Sign-in and Account Access | D7: CL-ACC-01 | E7: Sign in | F7: Open Sign in, enter the client email and password, and use the eye icon to show the password before signing in. | G7: The password can be shown and hidden. A Signed in message appears and the dashboard opens. | H7: Use the client account issued for UAT.
A8: Client | B8: CL-ACC | C8: CL-ACC · Sign-in and Account Access | D8: CL-ACC-02 | E8: Wrong password | F8: Sign in with the right email and a wrong password. | G8: An error message appears and you stay on the sign-in page. | H8: Use the client account issued for UAT.
A9: Client | B9: CL-ACC | C9: CL-ACC · Sign-in and Account Access | D9: CL-ACC-03 | E9: Wrong portal account | F9: Sign in here with a supplier or PMCM account. | G9: You are refused with a message that names the correct portal. | H9: Use the client account issued for UAT.
A10: Client | B10: CL-ACC | C10: CL-ACC · Sign-in and Account Access | D10: CL-ACC-04 | E10: Protected pages | F10: While signed out, open the /dashboard address directly. Sign in on the page that appears. | G10: You are sent to sign in first, then returned to the dashboard after signing in. | H10: Use the client account issued for UAT.
A11: Client | B11: CL-ACC | C11: CL-ACC · Sign-in and Account Access | D11: CL-ACC-05 | E11: Password reset request | F11: Click Forgot password, enter your email and click Request reset. | G11: A status message confirms the request. | H11: Use the client account issued for UAT.
A12: Client | B12: CL-ACC | C12: CL-ACC · Sign-in and Account Access | D12: CL-ACC-06 | E12: Sign out | F12: Sign out, then press the browser Back button. | G12: You are signed out and the dashboard is not shown again without signing in. | H12: Use the client account issued for UAT.
... A198: Coordinator | B198: CO-REG | C198: CO-REG · Registration Desk | D198: CO-REG-04 | E198: Archived event | F198: Switch to an archived event and try to check in a guest. | G198: The roster can be read but check-in is refused. | H198: Sign in as a Registration Staff coordinator assigned to the event.

Sheet Responses
A1: Submission ID | B1: Test Date | C1: Tester | D1: User Role | E1: Module | F1: Test Case ID | G1: Test Case | H1: Satisfaction Level | I1: Comment | J1: Check
J2: =IF($F2="","",IF($H2="","Not rated",IF(OR($H2=Lists!$B$3,$H2=Lists!$B$5),IF(AND(LEFT(SUBSTITUTE($I2," ",""),LEN($F2)+1)=$F2&"-",LEN(SUBSTITUTE($I2," ",""))>LEN($F2)+1),"OK","Comment required"),"OK")))
J3: =IF($F3="","",IF($H3="","Not rated",IF(OR($H3=Lists!$B$3,$H3=Lists!$B$5),IF(AND(LEFT(SUBSTITUTE($I3," ",""),LEN($F3)+1)=$F3&"-",LEN(SUBSTITUTE($I3," ",""))>LEN($F3)+1),"OK","Comment required"),"OK")))
J4: =IF($F4="","",IF($H4="","Not rated",IF(OR($H4=Lists!$B$3,$H4=Lists!$B$5),IF(AND(LEFT(SUBSTITUTE($I4," ",""),LEN($F4)+1)=$F4&"-",LEN(SUBSTITUTE($I4," ",""))>LEN($F4)+1),"OK","Comment required"),"OK")))
J5: =IF($F5="","",IF($H5="","Not rated",IF(OR($H5=Lists!$B$3,$H5=Lists!$B$5),IF(AND(LEFT(SUBSTITUTE($I5," ",""),LEN($F5)+1)=$F5&"-",LEN(SUBSTITUTE($I5," ",""))>LEN($F5)+1),"OK","Comment required"),"OK")))
J6: =IF($F6="","",IF($H6="","Not rated",IF(OR($H6=Lists!$B$3,$H6=Lists!$B$5),IF(AND(LEFT(SUBSTITUTE($I6," ",""),LEN($F6)+1)=$F6&"-",LEN(SUBSTITUTE($I6," ",""))>LEN($F6)+1),"OK","Comment required"),"OK")))
J7: =IF($F7="","",IF($H7="","Not rated",IF(OR($H7=Lists!$B$3,$H7=Lists!$B$5),IF(AND(LEFT(SUBSTITUTE($I7," ",""),LEN($F7)+1)=$F7&"-",LEN(SUBSTITUTE($I7," ",""))>LEN($F7)+1),"OK","Comment required"),"OK")))
J8: =IF($F8="","",IF($H8="","Not rated",IF(OR($H8=Lists!$B$3,$H8=Lists!$B$5),IF(AND(LEFT(SUBSTITUTE($I8," ",""),LEN($F8)+1)=$F8&"-",LEN(SUBSTITUTE($I8," ",""))>LEN($F8)+1),"OK","Comment required"),"OK")))
J9: =IF($F9="","",IF($H9="","Not rated",IF(OR($H9=Lists!$B$3,$H9=Lists!$B$5),IF(AND(LEFT(SUBSTITUTE($I9," ",""),LEN($F9)+1)=$F9&"-",LEN(SUBSTITUTE($I9," ",""))>LEN($F9)+1),"OK","Comment required"),"OK")))
J10: =IF($F10="","",IF($H10="","Not rated",IF(OR($H10=Lists!$B$3,$H10=Lists!$B$5),IF(AND(LEFT(SUBSTITUTE($I10," ",""),LEN($F10)+1)=$F10&"-",LEN(SUBSTITUTE($I10," ",""))>LEN($F10)+1),"OK","Comment required"),"OK")))
J11: =IF($F11="","",IF($H11="","Not rated",IF(OR($H11=Lists!$B$3,$H11=Lists!$B$5),IF(AND(LEFT(SUBSTITUTE($I11," ",""),LEN($F11)+1)=$F11&"-",LEN(SUBSTITUTE($I11," ",""))>LEN($F11)+1),"OK","Comment required"),"OK")))
J12: =IF($F12="","",IF($H12="","Not rated",IF(OR($H12=Lists!$B$3,$H12=Lists!$B$5),IF(AND(LEFT(SUBSTITUTE($I12," ",""),LEN($F12)+1)=$F12&"-",LEN(SUBSTITUTE($I12," ",""))>LEN($F12)+1),"OK","Comment required"),"OK")))
J13: =IF($F13="","",IF($H13="","Not rated",IF(OR($H13=Lists!$B$3,$H13=Lists!$B$5),IF(AND(LEFT(SUBSTITUTE($I13," ",""),LEN($F13)+1)=$F13&"-",LEN(SUBSTITUTE($I13," ",""))>LEN($F13)+1),"OK","Comment required"),"OK")))
... J2001: =IF($F2001="","",IF($H2001="","Not rated",IF(OR($H2001=Lists!$B$3,$H2001=Lists!$B$5),IF(AND(LEFT(SUBSTITUTE($I2001," ",""),LEN($F2001)+1)=$F2001&"-",LEN(SUBSTITUTE($I2001," ",""))>LEN($F2001)+1),"OK","Comment required"),"OK")))

Sheet Summary
A1: UAT Summary
A2: Counts come from the Responses sheet. Pass rate = Passed ÷ results recorded.
A3: Role | B3: Module | C3: Test Cases | D3: Passed | E3: Partially Passed | F3: Fail | G3: Skipped | H3: Results Recorded | I3: Pass Rate | J3: Comments Missing
A4: Client | B4: All Client modules | C4: =COUNTIF('Test Cases'!$A:$A,$A4) | D4: =COUNTIFS(Responses!$D:$D,$A4,Responses!$H:$H,Lists!$B$2) | E4: =COUNTIFS(Responses!$D:$D,$A4,Responses!$H:$H,Lists!$B$3) | F4: =COUNTIFS(Responses!$D:$D,$A4,Responses!$H:$H,Lists!$B$4) | G4: =COUNTIFS(Responses!$D:$D,$A4,Responses!$H:$H,Lists!$B$5) | H4: =SUM(D4:G4) | I4: =IF(H4=0,"-",D4/H4) | J4: =COUNTIFS(Responses!$D:$D,$A4,Responses!$J:$J,"Comment required")
A5: Client | B5: CL-INQ · Public Inquiry | C5: =COUNTIF('Test Cases'!$C:$C,$B5) | D5: =COUNTIFS(Responses!$E:$E,$B5,Responses!$H:$H,Lists!$B$2) | E5: =COUNTIFS(Responses!$E:$E,$B5,Responses!$H:$H,Lists!$B$3) | F5: =COUNTIFS(Responses!$E:$E,$B5,Responses!$H:$H,Lists!$B$4) | G5: =COUNTIFS(Responses!$E:$E,$B5,Responses!$H:$H,Lists!$B$5) | H5: =SUM(D5:G5) | I5: =IF(H5=0,"-",D5/H5) | J5: =COUNTIFS(Responses!$E:$E,$B5,Responses!$J:$J,"Comment required")
A6: Client | B6: CL-ACC · Sign-in and Account Access | C6: =COUNTIF('Test Cases'!$C:$C,$B6) | D6: =COUNTIFS(Responses!$E:$E,$B6,Responses!$H:$H,Lists!$B$2) | E6: =COUNTIFS(Responses!$E:$E,$B6,Responses!$H:$H,Lists!$B$3) | F6: =COUNTIFS(Responses!$E:$E,$B6,Responses!$H:$H,Lists!$B$4) | G6: =COUNTIFS(Responses!$E:$E,$B6,Responses!$H:$H,Lists!$B$5) | H6: =SUM(D6:G6) | I6: =IF(H6=0,"-",D6/H6) | J6: =COUNTIFS(Responses!$E:$E,$B6,Responses!$J:$J,"Comment required")
A7: Client | B7: CL-CON · Conforme | C7: =COUNTIF('Test Cases'!$C:$C,$B7) | D7: =COUNTIFS(Responses!$E:$E,$B7,Responses!$H:$H,Lists!$B$2) | E7: =COUNTIFS(Responses!$E:$E,$B7,Responses!$H:$H,Lists!$B$3) | F7: =COUNTIFS(Responses!$E:$E,$B7,Responses!$H:$H,Lists!$B$4) | G7: =COUNTIFS(Responses!$E:$E,$B7,Responses!$H:$H,Lists!$B$5) | H7: =SUM(D7:G7) | I7: =IF(H7=0,"-",D7/H7) | J7: =COUNTIFS(Responses!$E:$E,$B7,Responses!$J:$J,"Comment required")
A8: Client | B8: CL-DSH · Dashboard and My Events | C8: =COUNTIF('Test Cases'!$C:$C,$B8) | D8: =COUNTIFS(Responses!$E:$E,$B8,Responses!$H:$H,Lists!$B$2) | E8: =COUNTIFS(Responses!$E:$E,$B8,Responses!$H:$H,Lists!$B$3) | F8: =COUNTIFS(Responses!$E:$E,$B8,Responses!$H:$H,Lists!$B$4) | G8: =COUNTIFS(Responses!$E:$E,$B8,Responses!$H:$H,Lists!$B$5) | H8: =SUM(D8:G8) | I8: =IF(H8=0,"-",D8/H8) | J8: =COUNTIFS(Responses!$E:$E,$B8,Responses!$J:$J,"Comment required")
A9: Client | B9: CL-REQ · New Event Request | C9: =COUNTIF('Test Cases'!$C:$C,$B9) | D9: =COUNTIFS(Responses!$E:$E,$B9,Responses!$H:$H,Lists!$B$2) | E9: =COUNTIFS(Responses!$E:$E,$B9,Responses!$H:$H,Lists!$B$3) | F9: =COUNTIFS(Responses!$E:$E,$B9,Responses!$H:$H,Lists!$B$4) | G9: =COUNTIFS(Responses!$E:$E,$B9,Responses!$H:$H,Lists!$B$5) | H9: =SUM(D9:G9) | I9: =IF(H9=0,"-",D9/H9) | J9: =COUNTIFS(Responses!$E:$E,$B9,Responses!$J:$J,"Comment required")
A10: Client | B10: CL-EVT · Event Workspace and Change Requests | C10: =COUNTIF('Test Cases'!$C:$C,$B10) | D10: =COUNTIFS(Responses!$E:$E,$B10,Responses!$H:$H,Lists!$B$2) | E10: =COUNTIFS(Responses!$E:$E,$B10,Responses!$H:$H,Lists!$B$3) | F10: =COUNTIFS(Responses!$E:$E,$B10,Responses!$H:$H,Lists!$B$4) | G10: =COUNTIFS(Responses!$E:$E,$B10,Responses!$H:$H,Lists!$B$5) | H10: =SUM(D10:G10) | I10: =IF(H10=0,"-",D10/H10) | J10: =COUNTIFS(Responses!$E:$E,$B10,Responses!$J:$J,"Comment required")
A11: Client | B11: CL-BRF · Briefing and Proposal | C11: =COUNTIF('Test Cases'!$C:$C,$B11) | D11: =COUNTIFS(Responses!$E:$E,$B11,Responses!$H:$H,Lists!$B$2) | E11: =COUNTIFS(Responses!$E:$E,$B11,Responses!$H:$H,Lists!$B$3) | F11: =COUNTIFS(Responses!$E:$E,$B11,Responses!$H:$H,Lists!$B$4) | G11: =COUNTIFS(Responses!$E:$E,$B11,Responses!$H:$H,Lists!$B$5) | H11: =SUM(D11:G11) | I11: =IF(H11=0,"-",D11/H11) | J11: =COUNTIFS(Responses!$E:$E,$B11,Responses!$J:$J,"Comment required")
A12: Client | B12: CL-FLR · Floor Plan | C12: =COUNTIF('Test Cases'!$C:$C,$B12) | D12: =COUNTIFS(Responses!$E:$E,$B12,Responses!$H:$H,Lists!$B$2) | E12: =COUNTIFS(Responses!$E:$E,$B12,Responses!$H:$H,Lists!$B$3) | F12: =COUNTIFS(Responses!$E:$E,$B12,Responses!$H:$H,Lists!$B$4) | G12: =COUNTIFS(Responses!$E:$E,$B12,Responses!$H:$H,Lists!$B$5) | H12: =SUM(D12:G12) | I12: =IF(H12=0,"-",D12/H12) | J12: =COUNTIFS(Responses!$E:$E,$B12,Responses!$J:$J,"Comment required")
A13: Client | B13: CL-FIL · Files and Documents | C13: =COUNTIF('Test Cases'!$C:$C,$B13) | D13: =COUNTIFS(Responses!$E:$E,$B13,Responses!$H:$H,Lists!$B$2) | E13: =COUNTIFS(Responses!$E:$E,$B13,Responses!$H:$H,Lists!$B$3) | F13: =COUNTIFS(Responses!$E:$E,$B13,Responses!$H:$H,Lists!$B$4) | G13: =COUNTIFS(Responses!$E:$E,$B13,Responses!$H:$H,Lists!$B$5) | H13: =SUM(D13:G13) | I13: =IF(H13=0,"-",D13/H13) | J13: =COUNTIFS(Responses!$E:$E,$B13,Responses!$J:$J,"Comment required")
A14: Client | B14: CL-BIL · Billing | C14: =COUNTIF('Test Cases'!$C:$C,$B14) | D14: =COUNTIFS(Responses!$E:$E,$B14,Responses!$H:$H,Lists!$B$2) | E14: =COUNTIFS(Responses!$E:$E,$B14,Responses!$H:$H,Lists!$B$3) | F14: =COUNTIFS(Responses!$E:$E,$B14,Responses!$H:$H,Lists!$B$4) | G14: =COUNTIFS(Responses!$E:$E,$B14,Responses!$H:$H,Lists!$B$5) | H14: =SUM(D14:G14) | I14: =IF(H14=0,"-",D14/H14) | J14: =COUNTIFS(Responses!$E:$E,$B14,Responses!$J:$J,"Comment required")
A15: Client | B15: CL-MSG · Messages | C15: =COUNTIF('Test Cases'!$C:$C,$B15) | D15: =COUNTIFS(Responses!$E:$E,$B15,Responses!$H:$H,Lists!$B$2) | E15: =COUNTIFS(Responses!$E:$E,$B15,Responses!$H:$H,Lists!$B$3) | F15: =COUNTIFS(Responses!$E:$E,$B15,Responses!$H:$H,Lists!$B$4) | G15: =COUNTIFS(Responses!$E:$E,$B15,Responses!$H:$H,Lists!$B$5) | H15: =SUM(D15:G15) | I15: =IF(H15=0,"-",D15/H15) | J15: =COUNTIFS(Responses!$E:$E,$B15,Responses!$J:$J,"Comment required")
A16: Client | B16: CL-CAL · Calendar and Approvals | C16: =COUNTIF('Test Cases'!$C:$C,$B16) | D16: =COUNTIFS(Responses!$E:$E,$B16,Responses!$H:$H,Lists!$B$2) | E16: =COUNTIFS(Responses!$E:$E,$B16,Responses!$H:$H,Lists!$B$3) | F16: =COUNTIFS(Responses!$E:$E,$B16,Responses!$H:$H,Lists!$B$4) | G16: =COUNTIFS(Responses!$E:$E,$B16,Responses!$H:$H,Lists!$B$5) | H16: =SUM(D16:G16) | I16: =IF(H16=0,"-",D16/H16) | J16: =COUNTIFS(Responses!$E:$E,$B16,Responses!$J:$J,"Comment required")
A17: Client | B17: CL-CLO · Event Closeout | C17: =COUNTIF('Test Cases'!$C:$C,$B17) | D17: =COUNTIFS(Responses!$E:$E,$B17,Responses!$H:$H,Lists!$B$2) | E17: =COUNTIFS(Responses!$E:$E,$B17,Responses!$H:$H,Lists!$B$3) | F17: =COUNTIFS(Responses!$E:$E,$B17,Responses!$H:$H,Lists!$B$4) | G17: =COUNTIFS(Responses!$E:$E,$B17,Responses!$H:$H,Lists!$B$5) | H17: =SUM(D17:G17) | I17: =IF(H17=0,"-",D17/H17) | J17: =COUNTIFS(Responses!$E:$E,$B17,Responses!$J:$J,"Comment required")
A18: Supplier | B18: All Supplier modules | C18: =COUNTIF('Test Cases'!$A:$A,$A18) | D18: =COUNTIFS(Responses!$D:$D,$A18,Responses!$H:$H,Lists!$B$2) | E18: =COUNTIFS(Responses!$D:$D,$A18,Responses!$H:$H,Lists!$B$3) | F18: =COUNTIFS(Responses!$D:$D,$A18,Responses!$H:$H,Lists!$B$4) | G18: =COUNTIFS(Responses!$D:$D,$A18,Responses!$H:$H,Lists!$B$5) | H18: =SUM(D18:G18) | I18: =IF(H18=0,"-",D18/H18) | J18: =COUNTIFS(Responses!$D:$D,$A18,Responses!$J:$J,"Comment required")
A19: Supplier | B19: SU-APP · Supplier Application | C19: =COUNTIF('Test Cases'!$C:$C,$B19) | D19: =COUNTIFS(Responses!$E:$E,$B19,Responses!$H:$H,Lists!$B$2) | E19: =COUNTIFS(Responses!$E:$E,$B19,Responses!$H:$H,Lists!$B$3) | F19: =COUNTIFS(Responses!$E:$E,$B19,Responses!$H:$H,Lists!$B$4) | G19: =COUNTIFS(Responses!$E:$E,$B19,Responses!$H:$H,Lists!$B$5) | H19: =SUM(D19:G19) | I19: =IF(H19=0,"-",D19/H19) | J19: =COUNTIFS(Responses!$E:$E,$B19,Responses!$J:$J,"Comment required")
A20: Supplier | B20: SU-ACC · Sign-in and Account Access | C20: =COUNTIF('Test Cases'!$C:$C,$B20) | D20: =COUNTIFS(Responses!$E:$E,$B20,Responses!$H:$H,Lists!$B$2) | E20: =COUNTIFS(Responses!$E:$E,$B20,Responses!$H:$H,Lists!$B$3) | F20: =COUNTIFS(Responses!$E:$E,$B20,Responses!$H:$H,Lists!$B$4) | G20: =COUNTIFS(Responses!$E:$E,$B20,Responses!$H:$H,Lists!$B$5) | H20: =SUM(D20:G20) | I20: =IF(H20=0,"-",D20/H20) | J20: =COUNTIFS(Responses!$E:$E,$B20,Responses!$J:$J,"Comment required")
A21: Supplier | B21: SU-DSH · Dashboard Overview and Calendar | C21: =COUNTIF('Test Cases'!$C:$C,$B21) | D21: =COUNTIFS(Responses!$E:$E,$B21,Responses!$H:$H,Lists!$B$2) | E21: =COUNTIFS(Responses!$E:$E,$B21,Responses!$H:$H,Lists!$B$3) | F21: =COUNTIFS(Responses!$E:$E,$B21,Responses!$H:$H,Lists!$B$4) | G21: =COUNTIFS(Responses!$E:$E,$B21,Responses!$H:$H,Lists!$B$5) | H21: =SUM(D21:G21) | I21: =IF(H21=0,"-",D21/H21) | J21: =COUNTIFS(Responses!$E:$E,$B21,Responses!$J:$J,"Comment required")
A22: Supplier | B22: SU-QUO · Quote Requests and Quotations | C22: =COUNTIF('Test Cases'!$C:$C,$B22) | D22: =COUNTIFS(Responses!$E:$E,$B22,Responses!$H:$H,Lists!$B$2) | E22: =COUNTIFS(Responses!$E:$E,$B22,Responses!$H:$H,Lists!$B$3) | F22: =COUNTIFS(Responses!$E:$E,$B22,Responses!$H:$H,Lists!$B$4) | G22: =COUNTIFS(Responses!$E:$E,$B22,Responses!$H:$H,Lists!$B$5) | H22: =SUM(D22:G22) | I22: =IF(H22=0,"-",D22/H22) | J22: =COUNTIFS(Responses!$E:$E,$B22,Responses!$J:$J,"Comment required")
A23: Supplier | B23: SU-BKG · Bookings, Contracts and Event Day | C23: =COUNTIF('Test Cases'!$C:$C,$B23) | D23: =COUNTIFS(Responses!$E:$E,$B23,Responses!$H:$H,Lists!$B$2) | E23: =COUNTIFS(Responses!$E:$E,$B23,Responses!$H:$H,Lists!$B$3) | F23: =COUNTIFS(Responses!$E:$E,$B23,Responses!$H:$H,Lists!$B$4) | G23: =COUNTIFS(Responses!$E:$E,$B23,Responses!$H:$H,Lists!$B$5) | H23: =SUM(D23:G23) | I23: =IF(H23=0,"-",D23/H23) | J23: =COUNTIFS(Responses!$E:$E,$B23,Responses!$J:$J,"Comment required")
A24: Supplier | B24: SU-FIL · Files, Payments and Profile | C24: =COUNTIF('Test Cases'!$C:$C,$B24) | D24: =COUNTIFS(Responses!$E:$E,$B24,Responses!$H:$H,Lists!$B$2) | E24: =COUNTIFS(Responses!$E:$E,$B24,Responses!$H:$H,Lists!$B$3) | F24: =COUNTIFS(Responses!$E:$E,$B24,Responses!$H:$H,Lists!$B$4) | G24: =COUNTIFS(Responses!$E:$E,$B24,Responses!$H:$H,Lists!$B$5) | H24: =SUM(D24:G24) | I24: =IF(H24=0,"-",D24/H24) | J24: =COUNTIFS(Responses!$E:$E,$B24,Responses!$J:$J,"Comment required")
A25: Supplier | B25: SU-MSG · Messages | C25: =COUNTIF('Test Cases'!$C:$C,$B25) | D25: =COUNTIFS(Responses!$E:$E,$B25,Responses!$H:$H,Lists!$B$2) | E25: =COUNTIFS(Responses!$E:$E,$B25,Responses!$H:$H,Lists!$B$3) | F25: =COUNTIFS(Responses!$E:$E,$B25,Responses!$H:$H,Lists!$B$4) | G25: =COUNTIFS(Responses!$E:$E,$B25,Responses!$H:$H,Lists!$B$5) | H25: =SUM(D25:G25) | I25: =IF(H25=0,"-",D25/H25) | J25: =COUNTIFS(Responses!$E:$E,$B25,Responses!$J:$J,"Comment required")
A26: Guest | B26: All Guest modules | C26: =COUNTIF('Test Cases'!$A:$A,$A26) | D26: =COUNTIFS(Responses!$D:$D,$A26,Responses!$H:$H,Lists!$B$2) | E26: =COUNTIFS(Responses!$D:$D,$A26,Responses!$H:$H,Lists!$B$3) | F26: =COUNTIFS(Responses!$D:$D,$A26,Responses!$H:$H,Lists!$B$4) | G26: =COUNTIFS(Responses!$D:$D,$A26,Responses!$H:$H,Lists!$B$5) | H26: =SUM(D26:G26) | I26: =IF(H26=0,"-",D26/H26) | J26: =COUNTIFS(Responses!$D:$D,$A26,Responses!$J:$J,"Comment required")
A27: Guest | B27: GU-OPN · Open Event with Access Code | C27: =COUNTIF('Test Cases'!$C:$C,$B27) | D27: =COUNTIFS(Responses!$E:$E,$B27,Responses!$H:$H,Lists!$B$2) | E27: =COUNTIFS(Responses!$E:$E,$B27,Responses!$H:$H,Lists!$B$3) | F27: =COUNTIFS(Responses!$E:$E,$B27,Responses!$H:$H,Lists!$B$4) | G27: =COUNTIFS(Responses!$E:$E,$B27,Responses!$H:$H,Lists!$B$5) | H27: =SUM(D27:G27) | I27: =IF(H27=0,"-",D27/H27) | J27: =COUNTIFS(Responses!$E:$E,$B27,Responses!$J:$J,"Comment required")
A28: Guest | B28: GU-PAS · Event Pass and Details | C28: =COUNTIF('Test Cases'!$C:$C,$B28) | D28: =COUNTIFS(Responses!$E:$E,$B28,Responses!$H:$H,Lists!$B$2) | E28: =COUNTIFS(Responses!$E:$E,$B28,Responses!$H:$H,Lists!$B$3) | F28: =COUNTIFS(Responses!$E:$E,$B28,Responses!$H:$H,Lists!$B$4) | G28: =COUNTIFS(Responses!$E:$E,$B28,Responses!$H:$H,Lists!$B$5) | H28: =SUM(D28:G28) | I28: =IF(H28=0,"-",D28/H28) | J28: =COUNTIFS(Responses!$E:$E,$B28,Responses!$J:$J,"Comment required")
A29: Guest | B29: GU-CHK · Check-in | C29: =COUNTIF('Test Cases'!$C:$C,$B29) | D29: =COUNTIFS(Responses!$E:$E,$B29,Responses!$H:$H,Lists!$B$2) | E29: =COUNTIFS(Responses!$E:$E,$B29,Responses!$H:$H,Lists!$B$3) | F29: =COUNTIFS(Responses!$E:$E,$B29,Responses!$H:$H,Lists!$B$4) | G29: =COUNTIFS(Responses!$E:$E,$B29,Responses!$H:$H,Lists!$B$5) | H29: =SUM(D29:G29) | I29: =IF(H29=0,"-",D29/H29) | J29: =COUNTIFS(Responses!$E:$E,$B29,Responses!$J:$J,"Comment required")
A30: Guest | B30: GU-FBK · Feedback | C30: =COUNTIF('Test Cases'!$C:$C,$B30) | D30: =COUNTIFS(Responses!$E:$E,$B30,Responses!$H:$H,Lists!$B$2) | E30: =COUNTIFS(Responses!$E:$E,$B30,Responses!$H:$H,Lists!$B$3) | F30: =COUNTIFS(Responses!$E:$E,$B30,Responses!$H:$H,Lists!$B$4) | G30: =COUNTIFS(Responses!$E:$E,$B30,Responses!$H:$H,Lists!$B$5) | H30: =SUM(D30:G30) | I30: =IF(H30=0,"-",D30/H30) | J30: =COUNTIFS(Responses!$E:$E,$B30,Responses!$J:$J,"Comment required")
A31: Guest | B31: GU-GAM · Event Games | C31: =COUNTIF('Test Cases'!$C:$C,$B31) | D31: =COUNTIFS(Responses!$E:$E,$B31,Responses!$H:$H,Lists!$B$2) | E31: =COUNTIFS(Responses!$E:$E,$B31,Responses!$H:$H,Lists!$B$3) | F31: =COUNTIFS(Responses!$E:$E,$B31,Responses!$H:$H,Lists!$B$4) | G31: =COUNTIFS(Responses!$E:$E,$B31,Responses!$H:$H,Lists!$B$5) | H31: =SUM(D31:G31) | I31: =IF(H31=0,"-",D31/H31) | J31: =COUNTIFS(Responses!$E:$E,$B31,Responses!$J:$J,"Comment required")
A32: PMCM Admin | B32: All PMCM Admin modules | C32: =COUNTIF('Test Cases'!$A:$A,$A32) | D32: =COUNTIFS(Responses!$D:$D,$A32,Responses!$H:$H,Lists!$B$2) | E32: =COUNTIFS(Responses!$D:$D,$A32,Responses!$H:$H,Lists!$B$3) | F32: =COUNTIFS(Responses!$D:$D,$A32,Responses!$H:$H,Lists!$B$4) | G32: =COUNTIFS(Responses!$D:$D,$A32,Responses!$H:$H,Lists!$B$5) | H32: =SUM(D32:G32) | I32: =IF(H32=0,"-",D32/H32) | J32: =COUNTIFS(Responses!$D:$D,$A32,Responses!$J:$J,"Comment required")
A33: PMCM Admin | B33: AD-ACC · Sign-in and Account Access | C33: =COUNTIF('Test Cases'!$C:$C,$B33) | D33: =COUNTIFS(Responses!$E:$E,$B33,Responses!$H:$H,Lists!$B$2) | E33: =COUNTIFS(Responses!$E:$E,$B33,Responses!$H:$H,Lists!$B$3) | F33: =COUNTIFS(Responses!$E:$E,$B33,Responses!$H:$H,Lists!$B$4) | G33: =COUNTIFS(Responses!$E:$E,$B33,Responses!$H:$H,Lists!$B$5) | H33: =SUM(D33:G33) | I33: =IF(H33=0,"-",D33/H33) | J33: =COUNTIFS(Responses!$E:$E,$B33,Responses!$J:$J,"Comment required")
A34: PMCM Admin | B34: AD-INB · Dashboard and Command Inbox | C34: =COUNTIF('Test Cases'!$C:$C,$B34) | D34: =COUNTIFS(Responses!$E:$E,$B34,Responses!$H:$H,Lists!$B$2) | E34: =COUNTIFS(Responses!$E:$E,$B34,Responses!$H:$H,Lists!$B$3) | F34: =COUNTIFS(Responses!$E:$E,$B34,Responses!$H:$H,Lists!$B$4) | G34: =COUNTIFS(Responses!$E:$E,$B34,Responses!$H:$H,Lists!$B$5) | H34: =SUM(D34:G34) | I34: =IF(H34=0,"-",D34/H34) | J34: =COUNTIFS(Responses!$E:$E,$B34,Responses!$J:$J,"Comment required")
A35: PMCM Admin | B35: AD-INQ · Inquiries and Client Onboarding | C35: =COUNTIF('Test Cases'!$C:$C,$B35) | D35: =COUNTIFS(Responses!$E:$E,$B35,Responses!$H:$H,Lists!$B$2) | E35: =COUNTIFS(Responses!$E:$E,$B35,Responses!$H:$H,Lists!$B$3) | F35: =COUNTIFS(Responses!$E:$E,$B35,Responses!$H:$H,Lists!$B$4) | G35: =COUNTIFS(Responses!$E:$E,$B35,Responses!$H:$H,Lists!$B$5) | H35: =SUM(D35:G35) | I35: =IF(H35=0,"-",D35/H35) | J35: =COUNTIFS(Responses!$E:$E,$B35,Responses!$J:$J,"Comment required")
A36: PMCM Admin | B36: AD-CLI · Clients | C36: =COUNTIF('Test Cases'!$C:$C,$B36) | D36: =COUNTIFS(Responses!$E:$E,$B36,Responses!$H:$H,Lists!$B$2) | E36: =COUNTIFS(Responses!$E:$E,$B36,Responses!$H:$H,Lists!$B$3) | F36: =COUNTIFS(Responses!$E:$E,$B36,Responses!$H:$H,Lists!$B$4) | G36: =COUNTIFS(Responses!$E:$E,$B36,Responses!$H:$H,Lists!$B$5) | H36: =SUM(D36:G36) | I36: =IF(H36=0,"-",D36/H36) | J36: =COUNTIFS(Responses!$E:$E,$B36,Responses!$J:$J,"Comment required")
A37: PMCM Admin | B37: AD-TSK · Tasks and Ocular Visits | C37: =COUNTIF('Test Cases'!$C:$C,$B37) | D37: =COUNTIFS(Responses!$E:$E,$B37,Responses!$H:$H,Lists!$B$2) | E37: =COUNTIFS(Responses!$E:$E,$B37,Responses!$H:$H,Lists!$B$3) | F37: =COUNTIFS(Responses!$E:$E,$B37,Responses!$H:$H,Lists!$B$4) | G37: =COUNTIFS(Responses!$E:$E,$B37,Responses!$H:$H,Lists!$B$5) | H37: =SUM(D37:G37) | I37: =IF(H37=0,"-",D37/H37) | J37: =COUNTIFS(Responses!$E:$E,$B37,Responses!$J:$J,"Comment required")
A38: PMCM Admin | B38: AD-OVR · Event Overview, Briefing and Change Control | C38: =COUNTIF('Test Cases'!$C:$C,$B38) | D38: =COUNTIFS(Responses!$E:$E,$B38,Responses!$H:$H,Lists!$B$2) | E38: =COUNTIFS(Responses!$E:$E,$B38,Responses!$H:$H,Lists!$B$3) | F38: =COUNTIFS(Responses!$E:$E,$B38,Responses!$H:$H,Lists!$B$4) | G38: =COUNTIFS(Responses!$E:$E,$B38,Responses!$H:$H,Lists!$B$5) | H38: =SUM(D38:G38) | I38: =IF(H38=0,"-",D38/H38) | J38: =COUNTIFS(Responses!$E:$E,$B38,Responses!$J:$J,"Comment required")
A39: PMCM Admin | B39: AD-FLR · Floorplans | C39: =COUNTIF('Test Cases'!$C:$C,$B39) | D39: =COUNTIFS(Responses!$E:$E,$B39,Responses!$H:$H,Lists!$B$2) | E39: =COUNTIFS(Responses!$E:$E,$B39,Responses!$H:$H,Lists!$B$3) | F39: =COUNTIFS(Responses!$E:$E,$B39,Responses!$H:$H,Lists!$B$4) | G39: =COUNTIFS(Responses!$E:$E,$B39,Responses!$H:$H,Lists!$B$5) | H39: =SUM(D39:G39) | I39: =IF(H39=0,"-",D39/H39) | J39: =COUNTIFS(Responses!$E:$E,$B39,Responses!$J:$J,"Comment required")
A40: PMCM Admin | B40: AD-SUP · Event Suppliers | C40: =COUNTIF('Test Cases'!$C:$C,$B40) | D40: =COUNTIFS(Responses!$E:$E,$B40,Responses!$H:$H,Lists!$B$2) | E40: =COUNTIFS(Responses!$E:$E,$B40,Responses!$H:$H,Lists!$B$3) | F40: =COUNTIFS(Responses!$E:$E,$B40,Responses!$H:$H,Lists!$B$4) | G40: =COUNTIFS(Responses!$E:$E,$B40,Responses!$H:$H,Lists!$B$5) | H40: =SUM(D40:G40) | I40: =IF(H40=0,"-",D40/H40) | J40: =COUNTIFS(Responses!$E:$E,$B40,Responses!$J:$J,"Comment required")
...

Sheet Lists
A1: Roles | B1: Satisfaction Level | D1: Role | E1: Module
A2: Client | B2: Passed - Working | D2: Client | E2: CL-INQ · Public Inquiry
A3: Supplier | B3: Partially Passed - Works but needs revision (w/ comment) | D3: Client | E3: CL-ACC · Sign-in and Account Access
A4: Guest | B4: Fail - Not working | D4: Client | E4: CL-CON · Conforme
A5: PMCM Admin | B5: Skipped - Di tinest (w/ comment) | D5: Client | E5: CL-DSH · Dashboard and My Events
A6: Coordinator | D6: Client | E6: CL-REQ · New Event Request
D7: Client | E7: CL-EVT · Event Workspace and Change Requests
D8: Client | E8: CL-BRF · Briefing and Proposal
D9: Client | E9: CL-FLR · Floor Plan
D10: Client | E10: CL-FIL · Files and Documents
D11: Client | E11: CL-BIL · Billing
D12: Client | E12: CL-MSG · Messages
D13: Client | E13: CL-CAL · Calendar and Approvals
D14: Client | E14: CL-CLO · Event Closeout
D15: Supplier | E15: SU-APP · Supplier Application
D16: Supplier | E16: SU-ACC · Sign-in and Account Access
D17: Supplier | E17: SU-DSH · Dashboard Overview and Calendar
D18: Supplier | E18: SU-QUO · Quote Requests and Quotations
... D52: Coordinator | E52: CO-REG · Registration Desk
